2019-01-10 17:25:59,257 [WARNING] django.request: Bad Request: /
2019-01-10 17:26:02,253 [WARNING] django.request: Bad Request: /
2019-01-11 10:52:58,690 [WARNING] django.request: Not Found: /
2019-01-11 10:53:08,546 [WARNING] django.request: Not Found: /
2019-01-11 10:53:10,994 [WARNING] django.request: Not Found: /favicon.ico
2019-01-11 10:53:14,869 [WARNING] django.request: Not Found: /favicon.ico
2019-01-11 10:53:19,471 [WARNING] django.request: Not Found: /
2019-01-11 10:53:27,480 [WARNING] django.request: Not Found: /
2019-01-11 10:53:31,956 [ERROR] django.request: Internal Server Error: /check_version
Traceback (most recent call last):
  File "/Volumes/Work/ddtech/ddtenv/lib/python3.6/site-packages/django/core/handlers/exception.py", line 34, in inner
    response = get_response(request)
  File "/Volumes/Work/ddtech/ddtenv/lib/python3.6/site-packages/django/core/handlers/base.py", line 126, in _get_response
    response = self.process_exception_by_middleware(e, request)
  File "/Volumes/Work/ddtech/ddtenv/lib/python3.6/site-packages/django/core/handlers/base.py", line 124, in _get_response
    response = wrapped_callback(request, *callback_args, **callback_kwargs)
  File "/Volumes/Work/ddtech/aegis/employee/views.py", line 43, in checkVersion
    rqst = json.loads(request.body.decode("utf-8"))
  File "/Library/Frameworks/Python.framework/Versions/3.6/lib/python3.6/json/__init__.py", line 354, in loads
    return _default_decoder.decode(s)
  File "/Library/Frameworks/Python.framework/Versions/3.6/lib/python3.6/json/decoder.py", line 339, in decode
    obj, end = self.raw_decode(s, idx=_w(s, 0).end())
  File "/Library/Frameworks/Python.framework/Versions/3.6/lib/python3.6/json/decoder.py", line 357, in raw_decode
    raise JSONDecodeError("Expecting value", s, err.value) from None
json.decoder.JSONDecodeError: Expecting value: line 1 column 1 (char 0)
2019-01-11 10:53:32,034 [WARNING] django.request: Not Found: /favicon.ico
2019-01-11 10:55:00,766 [ERROR] django.request: Internal Server Error: /check_version
Traceback (most recent call last):
  File "/Volumes/Work/ddtech/ddtenv/lib/python3.6/site-packages/django/core/handlers/exception.py", line 34, in inner
    response = get_response(request)
  File "/Volumes/Work/ddtech/ddtenv/lib/python3.6/site-packages/django/core/handlers/base.py", line 126, in _get_response
    response = self.process_exception_by_middleware(e, request)
  File "/Volumes/Work/ddtech/ddtenv/lib/python3.6/site-packages/django/core/handlers/base.py", line 124, in _get_response
    response = wrapped_callback(request, *callback_args, **callback_kwargs)
  File "/Volumes/Work/ddtech/aegis/employee/views.py", line 43, in checkVersion
    rqst = json.loads(request.body.decode("utf-8"))
  File "/Library/Frameworks/Python.framework/Versions/3.6/lib/python3.6/json/__init__.py", line 354, in loads
    return _default_decoder.decode(s)
  File "/Library/Frameworks/Python.framework/Versions/3.6/lib/python3.6/json/decoder.py", line 339, in decode
    obj, end = self.raw_decode(s, idx=_w(s, 0).end())
  File "/Library/Frameworks/Python.framework/Versions/3.6/lib/python3.6/json/decoder.py", line 357, in raw_decode
    raise JSONDecodeError("Expecting value", s, err.value) from None
json.decoder.JSONDecodeError: Expecting value: line 1 column 1 (char 0)
2019-01-11 10:55:05,485 [WARNING] django.request: Not Found: /check_version&i=10
2019-01-11 10:55:05,509 [WARNING] django.request: Not Found: /favicon.ico
2019-01-11 10:55:10,886 [WARNING] django.request: Not Found: /check_version&i=10
2019-01-11 10:55:11,785 [ERROR] django.request: Internal Server Error: /check_version
Traceback (most recent call last):
  File "/Volumes/Work/ddtech/ddtenv/lib/python3.6/site-packages/django/core/handlers/exception.py", line 34, in inner
    response = get_response(request)
  File "/Volumes/Work/ddtech/ddtenv/lib/python3.6/site-packages/django/core/handlers/base.py", line 126, in _get_response
    response = self.process_exception_by_middleware(e, request)
  File "/Volumes/Work/ddtech/ddtenv/lib/python3.6/site-packages/django/core/handlers/base.py", line 124, in _get_response
    response = wrapped_callback(request, *callback_args, **callback_kwargs)
  File "/Volumes/Work/ddtech/aegis/employee/views.py", line 43, in checkVersion
    rqst = json.loads(request.body.decode("utf-8"))
  File "/Library/Frameworks/Python.framework/Versions/3.6/lib/python3.6/json/__init__.py", line 354, in loads
    return _default_decoder.decode(s)
  File "/Library/Frameworks/Python.framework/Versions/3.6/lib/python3.6/json/decoder.py", line 339, in decode
    obj, end = self.raw_decode(s, idx=_w(s, 0).end())
  File "/Library/Frameworks/Python.framework/Versions/3.6/lib/python3.6/json/decoder.py", line 357, in raw_decode
    raise JSONDecodeError("Expecting value", s, err.value) from None
json.decoder.JSONDecodeError: Expecting value: line 1 column 1 (char 0)
2019-01-11 10:55:14,777 [ERROR] django.request: Internal Server Error: /check_version
Traceback (most recent call last):
  File "/Volumes/Work/ddtech/ddtenv/lib/python3.6/site-packages/django/core/handlers/exception.py", line 34, in inner
    response = get_response(request)
  File "/Volumes/Work/ddtech/ddtenv/lib/python3.6/site-packages/django/core/handlers/base.py", line 126, in _get_response
    response = self.process_exception_by_middleware(e, request)
  File "/Volumes/Work/ddtech/ddtenv/lib/python3.6/site-packages/django/core/handlers/base.py", line 124, in _get_response
    response = wrapped_callback(request, *callback_args, **callback_kwargs)
  File "/Volumes/Work/ddtech/aegis/employee/views.py", line 43, in checkVersion
    rqst = json.loads(request.body.decode("utf-8"))
  File "/Library/Frameworks/Python.framework/Versions/3.6/lib/python3.6/json/__init__.py", line 354, in loads
    return _default_decoder.decode(s)
  File "/Library/Frameworks/Python.framework/Versions/3.6/lib/python3.6/json/decoder.py", line 339, in decode
    obj, end = self.raw_decode(s, idx=_w(s, 0).end())
  File "/Library/Frameworks/Python.framework/Versions/3.6/lib/python3.6/json/decoder.py", line 357, in raw_decode
    raise JSONDecodeError("Expecting value", s, err.value) from None
json.decoder.JSONDecodeError: Expecting value: line 1 column 1 (char 0)
2019-01-11 10:55:14,828 [WARNING] django.request: Not Found: /favicon.ico
2019-01-11 10:55:47,335 [ERROR] django.request: Internal Server Error: /check_version
Traceback (most recent call last):
  File "/Volumes/Work/ddtech/ddtenv/lib/python3.6/site-packages/django/core/handlers/exception.py", line 34, in inner
    response = get_response(request)
  File "/Volumes/Work/ddtech/ddtenv/lib/python3.6/site-packages/django/core/handlers/base.py", line 126, in _get_response
    response = self.process_exception_by_middleware(e, request)
  File "/Volumes/Work/ddtech/ddtenv/lib/python3.6/site-packages/django/core/handlers/base.py", line 124, in _get_response
    response = wrapped_callback(request, *callback_args, **callback_kwargs)
  File "/Volumes/Work/ddtech/aegis/employee/views.py", line 43, in checkVersion
    rqst = json.loads(request.body.decode("utf-8"))
  File "/Library/Frameworks/Python.framework/Versions/3.6/lib/python3.6/json/__init__.py", line 354, in loads
    return _default_decoder.decode(s)
  File "/Library/Frameworks/Python.framework/Versions/3.6/lib/python3.6/json/decoder.py", line 339, in decode
    obj, end = self.raw_decode(s, idx=_w(s, 0).end())
  File "/Library/Frameworks/Python.framework/Versions/3.6/lib/python3.6/json/decoder.py", line 357, in raw_decode
    raise JSONDecodeError("Expecting value", s, err.value) from None
json.decoder.JSONDecodeError: Expecting value: line 1 column 1 (char 0)
2019-01-11 10:58:28,102 [ERROR] django.request: Internal Server Error: /check_version
Traceback (most recent call last):
  File "/Volumes/Work/ddtech/ddtenv/lib/python3.6/site-packages/django/core/handlers/exception.py", line 34, in inner
    response = get_response(request)
  File "/Volumes/Work/ddtech/ddtenv/lib/python3.6/site-packages/django/core/handlers/base.py", line 126, in _get_response
    response = self.process_exception_by_middleware(e, request)
  File "/Volumes/Work/ddtech/ddtenv/lib/python3.6/site-packages/django/core/handlers/base.py", line 124, in _get_response
    response = wrapped_callback(request, *callback_args, **callback_kwargs)
  File "/Volumes/Work/ddtech/aegis/employee/views.py", line 46, in checkVersion
    rqst = request["GET"]
TypeError: 'WSGIRequest' object is not subscriptable
2019-01-11 10:58:45,037 [ERROR] django.request: Internal Server Error: /check_version
Traceback (most recent call last):
  File "/Volumes/Work/ddtech/ddtenv/lib/python3.6/site-packages/django/core/handlers/exception.py", line 34, in inner
    response = get_response(request)
  File "/Volumes/Work/ddtech/ddtenv/lib/python3.6/site-packages/django/core/handlers/base.py", line 126, in _get_response
    response = self.process_exception_by_middleware(e, request)
  File "/Volumes/Work/ddtech/ddtenv/lib/python3.6/site-packages/django/core/handlers/base.py", line 124, in _get_response
    response = wrapped_callback(request, *callback_args, **callback_kwargs)
  File "/Volumes/Work/ddtech/aegis/employee/views.py", line 46, in checkVersion
    rqst = request["GET"]
TypeError: 'WSGIRequest' object is not subscriptable
2019-01-11 10:58:46,637 [ERROR] django.request: Internal Server Error: /check_version
Traceback (most recent call last):
  File "/Volumes/Work/ddtech/ddtenv/lib/python3.6/site-packages/django/core/handlers/exception.py", line 34, in inner
    response = get_response(request)
  File "/Volumes/Work/ddtech/ddtenv/lib/python3.6/site-packages/django/core/handlers/base.py", line 126, in _get_response
    response = self.process_exception_by_middleware(e, request)
  File "/Volumes/Work/ddtech/ddtenv/lib/python3.6/site-packages/django/core/handlers/base.py", line 124, in _get_response
    response = wrapped_callback(request, *callback_args, **callback_kwargs)
  File "/Volumes/Work/ddtech/aegis/employee/views.py", line 46, in checkVersion
    rqst = request["GET"]
TypeError: 'WSGIRequest' object is not subscriptable
2019-01-11 11:20:27,421 [ERROR] django.request: Internal Server Error: /check_version
Traceback (most recent call last):
  File "/Volumes/Work/ddtech/ddtenv/lib/python3.6/site-packages/django/core/handlers/exception.py", line 34, in inner
    response = get_response(request)
  File "/Volumes/Work/ddtech/ddtenv/lib/python3.6/site-packages/django/core/handlers/base.py", line 126, in _get_response
    response = self.process_exception_by_middleware(e, request)
  File "/Volumes/Work/ddtech/ddtenv/lib/python3.6/site-packages/django/core/handlers/base.py", line 124, in _get_response
    response = wrapped_callback(request, *callback_args, **callback_kwargs)
  File "/Volumes/Work/ddtech/aegis/employee/views.py", line 48, in checkVersion
    return HttpResponse(json.dumps(result, cls=DateTimeEncoder))
NameError: name 'result' is not defined
2019-01-11 11:21:56,760 [WARNING] django.request: Not Found: /favicon.ico
2019-01-11 11:23:21,424 [ERROR] django.request: Internal Server Error: /check_version
Traceback (most recent call last):
  File "/Volumes/Work/ddtech/ddtenv/lib/python3.6/site-packages/django/core/handlers/exception.py", line 34, in inner
    response = get_response(request)
  File "/Volumes/Work/ddtech/ddtenv/lib/python3.6/site-packages/django/core/handlers/base.py", line 126, in _get_response
    response = self.process_exception_by_middleware(e, request)
  File "/Volumes/Work/ddtech/ddtenv/lib/python3.6/site-packages/django/core/handlers/base.py", line 124, in _get_response
    response = wrapped_callback(request, *callback_args, **callback_kwargs)
  File "/Volumes/Work/ddtech/aegis/employee/views.py", line 47, in checkVersion
    for key in rqst.allkeys:
AttributeError: 'QueryDict' object has no attribute 'allkeys'
2019-01-14 15:05:29,768 [WARNING] django.request: Not Acceptable: /
2019-01-14 15:07:04,099 [WARNING] django.request: Not Found: /favicon.ico
2019-01-14 15:25:22,195 [WARNING] django.request: Not Found: /favicon.ico
2019-01-14 15:37:53,518 [WARNING] django.request: Not Found: /favicon.ico
2019-01-14 15:39:05,493 [WARNING] django.request: Not Found: /
2019-01-14 15:39:09,165 [WARNING] django.request: Not Found: /api_auth
2019-01-14 15:39:09,186 [WARNING] django.request: Not Found: /favicon.ico
2019-01-14 15:39:21,112 [WARNING] django.request: Not Found: /api_auth/
2019-01-14 15:39:33,046 [WARNING] django.request: Not Found: /api_auth/
2019-01-14 15:39:33,190 [WARNING] django.request: Not Found: /api_auth
2019-01-14 15:39:34,554 [WARNING] django.request: Not Found: /
2019-01-14 15:42:14,880 [WARNING] django.request: Not Found: /
2019-01-14 15:42:15,561 [WARNING] django.request: Not Found: /api_auth
2019-01-14 15:42:17,621 [WARNING] django.request: Not Found: /favicon.ico
2019-01-14 15:42:33,900 [WARNING] django.request: Not Found: /favicon.ico
2019-01-14 15:47:17,345 [WARNING] django.request: Not Found: /api_auth
2019-01-14 15:47:18,695 [WARNING] django.request: Not Found: /api_auth
2019-01-14 15:47:37,876 [WARNING] django.request: Not Found: /api_auth/
2019-01-14 15:47:38,010 [WARNING] django.request: Not Found: /api_auth/
2019-01-14 15:47:45,363 [WARNING] django.request: Not Found: /api_auth
2019-01-14 15:47:46,362 [WARNING] django.request: Not Found: /api_auth
2019-01-14 15:47:46,726 [WARNING] django.request: Not Found: /
2019-01-14 16:00:58,580 [WARNING] django.request: Not Found: /
2019-01-14 16:13:02,283 [WARNING] django.request: Not Found: /
2019-01-14 16:13:03,168 [ERROR] django.request: Internal Server Error: /check_version
Traceback (most recent call last):
  File "/Volumes/Work/ddtech/ddtenv/lib/python3.6/site-packages/django/core/handlers/exception.py", line 34, in inner
    response = get_response(request)
  File "/Volumes/Work/ddtech/ddtenv/lib/python3.6/site-packages/django/core/handlers/base.py", line 126, in _get_response
    response = self.process_exception_by_middleware(e, request)
  File "/Volumes/Work/ddtech/ddtenv/lib/python3.6/site-packages/django/core/handlers/base.py", line 124, in _get_response
    response = wrapped_callback(request, *callback_args, **callback_kwargs)
  File "/Volumes/Work/ddtech/aegis/employee/views.py", line 51, in checkVersion
    resultJson = JsonResopnse(result)
NameError: name 'JsonResopnse' is not defined
2019-01-14 16:13:05,420 [ERROR] django.request: Internal Server Error: /check_version
Traceback (most recent call last):
  File "/Volumes/Work/ddtech/ddtenv/lib/python3.6/site-packages/django/core/handlers/exception.py", line 34, in inner
    response = get_response(request)
  File "/Volumes/Work/ddtech/ddtenv/lib/python3.6/site-packages/django/core/handlers/base.py", line 126, in _get_response
    response = self.process_exception_by_middleware(e, request)
  File "/Volumes/Work/ddtech/ddtenv/lib/python3.6/site-packages/django/core/handlers/base.py", line 124, in _get_response
    response = wrapped_callback(request, *callback_args, **callback_kwargs)
  File "/Volumes/Work/ddtech/aegis/employee/views.py", line 51, in checkVersion
    resultJson = JsonResopnse(result)
NameError: name 'JsonResopnse' is not defined
2019-01-14 16:13:46,867 [ERROR] django.request: Internal Server Error: /check_version
Traceback (most recent call last):
  File "/Volumes/Work/ddtech/ddtenv/lib/python3.6/site-packages/django/core/handlers/exception.py", line 34, in inner
    response = get_response(request)
  File "/Volumes/Work/ddtech/ddtenv/lib/python3.6/site-packages/django/core/handlers/base.py", line 126, in _get_response
    response = self.process_exception_by_middleware(e, request)
  File "/Volumes/Work/ddtech/ddtenv/lib/python3.6/site-packages/django/core/handlers/base.py", line 124, in _get_response
    response = wrapped_callback(request, *callback_args, **callback_kwargs)
  File "/Volumes/Work/ddtech/aegis/employee/views.py", line 51, in checkVersion
    resultJson = JsonResopnse(result)
NameError: name 'JsonResopnse' is not defined
2019-01-14 16:14:16,178 [ERROR] django.request: Internal Server Error: /check_version
Traceback (most recent call last):
  File "/Volumes/Work/ddtech/ddtenv/lib/python3.6/site-packages/django/core/handlers/exception.py", line 34, in inner
    response = get_response(request)
  File "/Volumes/Work/ddtech/ddtenv/lib/python3.6/site-packages/django/core/handlers/base.py", line 126, in _get_response
    response = self.process_exception_by_middleware(e, request)
  File "/Volumes/Work/ddtech/ddtenv/lib/python3.6/site-packages/django/core/handlers/base.py", line 124, in _get_response
    response = wrapped_callback(request, *callback_args, **callback_kwargs)
  File "/Volumes/Work/ddtech/aegis/employee/views.py", line 52, in checkVersion
    print(result.constent)
AttributeError: 'dict' object has no attribute 'constent'
2019-01-14 16:14:48,142 [ERROR] django.request: Internal Server Error: /check_version
Traceback (most recent call last):
  File "/Volumes/Work/ddtech/ddtenv/lib/python3.6/site-packages/django/core/handlers/exception.py", line 34, in inner
    response = get_response(request)
  File "/Volumes/Work/ddtech/ddtenv/lib/python3.6/site-packages/django/core/handlers/base.py", line 126, in _get_response
    response = self.process_exception_by_middleware(e, request)
  File "/Volumes/Work/ddtech/ddtenv/lib/python3.6/site-packages/django/core/handlers/base.py", line 124, in _get_response
    response = wrapped_callback(request, *callback_args, **callback_kwargs)
  File "/Volumes/Work/ddtech/aegis/employee/views.py", line 52, in checkVersion
    print(resultJson.constent)
AttributeError: 'JsonResponse' object has no attribute 'constent'
2019-01-14 16:18:20,453 [ERROR] django.request: Internal Server Error: /check_version
Traceback (most recent call last):
  File "/Volumes/Work/ddtech/ddtenv/lib/python3.6/site-packages/django/core/handlers/exception.py", line 34, in inner
    response = get_response(request)
  File "/Volumes/Work/ddtech/ddtenv/lib/python3.6/site-packages/django/core/handlers/base.py", line 126, in _get_response
    response = self.process_exception_by_middleware(e, request)
  File "/Volumes/Work/ddtech/ddtenv/lib/python3.6/site-packages/django/core/handlers/base.py", line 124, in _get_response
    response = wrapped_callback(request, *callback_args, **callback_kwargs)
  File "/Volumes/Work/ddtech/aegis/employee/views.py", line 53, in checkVersion
    response.content = json.dumps(result, cls=DateTimeEncoder)
AttributeError: 'int' object has no attribute 'content'
2019-01-14 16:22:48,183 [ERROR] django.request: Service Unavailable: /check_version
2019-01-14 16:23:45,203 [ERROR] django.request: Service Unavailable: /check_version
2019-01-14 16:24:03,013 [ERROR] django.request: Service Unavailable: /check_version
2019-01-14 16:50:13,966 [ERROR] django.request: Service Unavailable: /check_version
2019-01-14 16:50:15,917 [WARNING] django.request: Not Found: /
2019-01-14 16:50:20,112 [WARNING] django.request: Not Found: /rest_RSA
2019-01-14 16:50:20,133 [WARNING] django.request: Not Found: /favicon.ico
2019-01-14 16:50:56,038 [WARNING] django.request: Not Found: /rest_RSA
2019-01-14 16:50:57,464 [WARNING] django.request: Not Found: /rest_RSA
2019-01-14 16:50:58,690 [WARNING] django.request: Not Found: /rest_RSA
2019-01-14 16:51:10,244 [ERROR] django.request: Internal Server Error: /test_RSA
Traceback (most recent call last):
  File "/Volumes/Work/ddtech/ddtenv/lib/python3.6/site-packages/django/utils/datastructures.py", line 77, in __getitem__
    list_ = super().__getitem__(key)
KeyError: 'RSAPublicKey'

During handling of the above exception, another exception occurred:

Traceback (most recent call last):
  File "/Volumes/Work/ddtech/aegis/employee/views.py", line 95, in test_RSA
    rsapKey = request.GET["RSAPublicKey"]
  File "/Volumes/Work/ddtech/ddtenv/lib/python3.6/site-packages/django/utils/datastructures.py", line 79, in __getitem__
    raise MultiValueDictKeyError(key)
django.utils.datastructures.MultiValueDictKeyError: 'RSAPublicKey'

During handling of the above exception, another exception occurred:

Traceback (most recent call last):
  File "/Volumes/Work/ddtech/ddtenv/lib/python3.6/site-packages/django/core/handlers/exception.py", line 34, in inner
    response = get_response(request)
  File "/Volumes/Work/ddtech/ddtenv/lib/python3.6/site-packages/django/core/handlers/base.py", line 126, in _get_response
    response = self.process_exception_by_middleware(e, request)
  File "/Volumes/Work/ddtech/ddtenv/lib/python3.6/site-packages/django/core/handlers/base.py", line 124, in _get_response
    response = wrapped_callback(request, *callback_args, **callback_kwargs)
  File "/Volumes/Work/ddtech/aegis/employee/views.py", line 120, in test_RSA
    return exceptionError('mng_currentEnv', staffCode, e)
UnboundLocalError: local variable 'staffCode' referenced before assignment
2019-01-14 16:51:10,302 [WARNING] django.request: Not Found: /favicon.ico
2019-01-14 16:51:56,477 [ERROR] django.request: Internal Server Error: /test_RSA
Traceback (most recent call last):
  File "/Volumes/Work/ddtech/ddtenv/lib/python3.6/site-packages/django/utils/datastructures.py", line 77, in __getitem__
    list_ = super().__getitem__(key)
KeyError: 'RSAPublicKey'

During handling of the above exception, another exception occurred:

Traceback (most recent call last):
  File "/Volumes/Work/ddtech/aegis/employee/views.py", line 95, in test_RSA
    rsapKey = request.GET["RSAPublicKey"]
  File "/Volumes/Work/ddtech/ddtenv/lib/python3.6/site-packages/django/utils/datastructures.py", line 79, in __getitem__
    raise MultiValueDictKeyError(key)
django.utils.datastructures.MultiValueDictKeyError: 'RSAPublicKey'

During handling of the above exception, another exception occurred:

Traceback (most recent call last):
  File "/Volumes/Work/ddtech/ddtenv/lib/python3.6/site-packages/django/core/handlers/exception.py", line 34, in inner
    response = get_response(request)
  File "/Volumes/Work/ddtech/ddtenv/lib/python3.6/site-packages/django/core/handlers/base.py", line 126, in _get_response
    response = self.process_exception_by_middleware(e, request)
  File "/Volumes/Work/ddtech/ddtenv/lib/python3.6/site-packages/django/core/handlers/base.py", line 124, in _get_response
    response = wrapped_callback(request, *callback_args, **callback_kwargs)
  File "/Volumes/Work/ddtech/aegis/employee/views.py", line 121, in test_RSA
    eResponse = HttpResponse(json.dump({'R': 20, 'M': "에러 났어요"}))
TypeError: dump() missing 1 required positional argument: 'fp'
2019-01-14 16:52:59,955 [ERROR] django.request: Internal Server Error: /test_RSA
Traceback (most recent call last):
  File "/Volumes/Work/ddtech/ddtenv/lib/python3.6/site-packages/django/utils/datastructures.py", line 77, in __getitem__
    list_ = super().__getitem__(key)
KeyError: 'RSAPublicKey'

During handling of the above exception, another exception occurred:

Traceback (most recent call last):
  File "/Volumes/Work/ddtech/aegis/employee/views.py", line 95, in test_RSA
    rsapKey = request.GET["RSAPublicKey"]
  File "/Volumes/Work/ddtech/ddtenv/lib/python3.6/site-packages/django/utils/datastructures.py", line 79, in __getitem__
    raise MultiValueDictKeyError(key)
django.utils.datastructures.MultiValueDictKeyError: 'RSAPublicKey'

During handling of the above exception, another exception occurred:

Traceback (most recent call last):
  File "/Volumes/Work/ddtech/ddtenv/lib/python3.6/site-packages/django/core/handlers/exception.py", line 34, in inner
    response = get_response(request)
  File "/Volumes/Work/ddtech/ddtenv/lib/python3.6/site-packages/django/core/handlers/base.py", line 126, in _get_response
    response = self.process_exception_by_middleware(e, request)
  File "/Volumes/Work/ddtech/ddtenv/lib/python3.6/site-packages/django/core/handlers/base.py", line 124, in _get_response
    response = wrapped_callback(request, *callback_args, **callback_kwargs)
  File "/Volumes/Work/ddtech/aegis/employee/views.py", line 121, in test_RSA
    eResponse = HttpResponse(json.dump({'R': 20, 'M': "에러 났어요"}))
TypeError: dump() missing 1 required positional argument: 'fp'
2019-01-14 16:53:41,475 [ERROR] django.request: Internal Server Error: /test_RSA
Traceback (most recent call last):
  File "/Volumes/Work/ddtech/ddtenv/lib/python3.6/site-packages/django/utils/datastructures.py", line 77, in __getitem__
    list_ = super().__getitem__(key)
KeyError: 'RSAPublicKey'

During handling of the above exception, another exception occurred:

Traceback (most recent call last):
  File "/Volumes/Work/ddtech/aegis/employee/views.py", line 95, in test_RSA
    rsapKey = request.GET["RSAPublicKey"]
  File "/Volumes/Work/ddtech/ddtenv/lib/python3.6/site-packages/django/utils/datastructures.py", line 79, in __getitem__
    raise MultiValueDictKeyError(key)
django.utils.datastructures.MultiValueDictKeyError: 'RSAPublicKey'

During handling of the above exception, another exception occurred:

Traceback (most recent call last):
  File "/Volumes/Work/ddtech/ddtenv/lib/python3.6/site-packages/django/core/handlers/exception.py", line 34, in inner
    response = get_response(request)
  File "/Volumes/Work/ddtech/ddtenv/lib/python3.6/site-packages/django/core/handlers/base.py", line 126, in _get_response
    response = self.process_exception_by_middleware(e, request)
  File "/Volumes/Work/ddtech/ddtenv/lib/python3.6/site-packages/django/core/handlers/base.py", line 124, in _get_response
    response = wrapped_callback(request, *callback_args, **callback_kwargs)
  File "/Volumes/Work/ddtech/aegis/employee/views.py", line 121, in test_RSA
    eResponse = HttpResponse(json.dump({'R': 20, 'M': "에러 났어요"}))
TypeError: dump() missing 1 required positional argument: 'fp'
2019-01-14 16:54:15,066 [ERROR] django.request: Internal Server Error: /test_RSA
Traceback (most recent call last):
  File "/Volumes/Work/ddtech/ddtenv/lib/python3.6/site-packages/django/utils/datastructures.py", line 77, in __getitem__
    list_ = super().__getitem__(key)
KeyError: 'RSAPublicKey'

During handling of the above exception, another exception occurred:

Traceback (most recent call last):
  File "/Volumes/Work/ddtech/aegis/employee/views.py", line 95, in test_RSA
    rsapKey = request.GET["RSAPublicKey"]
  File "/Volumes/Work/ddtech/ddtenv/lib/python3.6/site-packages/django/utils/datastructures.py", line 79, in __getitem__
    raise MultiValueDictKeyError(key)
django.utils.datastructures.MultiValueDictKeyError: 'RSAPublicKey'

During handling of the above exception, another exception occurred:

Traceback (most recent call last):
  File "/Volumes/Work/ddtech/ddtenv/lib/python3.6/site-packages/django/core/handlers/exception.py", line 34, in inner
    response = get_response(request)
  File "/Volumes/Work/ddtech/ddtenv/lib/python3.6/site-packages/django/core/handlers/base.py", line 126, in _get_response
    response = self.process_exception_by_middleware(e, request)
  File "/Volumes/Work/ddtech/ddtenv/lib/python3.6/site-packages/django/core/handlers/base.py", line 124, in _get_response
    response = wrapped_callback(request, *callback_args, **callback_kwargs)
  File "/Volumes/Work/ddtech/aegis/employee/views.py", line 121, in test_RSA
    eResponse = HttpResponse(json.dump({'R': 20, 'M': "에러 났어요"}))
TypeError: dump() missing 1 required positional argument: 'fp'
2019-01-14 16:54:33,737 [ERROR] django.request: Internal Server Error: /test_RSA
Traceback (most recent call last):
  File "/Volumes/Work/ddtech/ddtenv/lib/python3.6/site-packages/django/utils/datastructures.py", line 77, in __getitem__
    list_ = super().__getitem__(key)
KeyError: 'RSAPublicKey'

During handling of the above exception, another exception occurred:

Traceback (most recent call last):
  File "/Volumes/Work/ddtech/aegis/employee/views.py", line 95, in test_RSA
    rsapKey = request.GET["RSAPublicKey"]
  File "/Volumes/Work/ddtech/ddtenv/lib/python3.6/site-packages/django/utils/datastructures.py", line 79, in __getitem__
    raise MultiValueDictKeyError(key)
django.utils.datastructures.MultiValueDictKeyError: 'RSAPublicKey'

During handling of the above exception, another exception occurred:

Traceback (most recent call last):
  File "/Volumes/Work/ddtech/ddtenv/lib/python3.6/site-packages/django/core/handlers/exception.py", line 34, in inner
    response = get_response(request)
  File "/Volumes/Work/ddtech/ddtenv/lib/python3.6/site-packages/django/core/handlers/base.py", line 126, in _get_response
    response = self.process_exception_by_middleware(e, request)
  File "/Volumes/Work/ddtech/ddtenv/lib/python3.6/site-packages/django/core/handlers/base.py", line 124, in _get_response
    response = wrapped_callback(request, *callback_args, **callback_kwargs)
  File "/Volumes/Work/ddtech/aegis/employee/views.py", line 121, in test_RSA
    eResponse = HttpResponse(json.dump({'R': 20, 'M': "에러 났어요"}))
TypeError: dump() missing 1 required positional argument: 'fp'
2019-01-14 16:55:47,858 [ERROR] django.request: Service Unavailable: /test_RSA
2019-01-14 16:56:38,312 [ERROR] django.request: Service Unavailable: /test_RSA
2019-01-14 16:56:44,206 [ERROR] django.request: Service Unavailable: /test_RSA
2019-01-14 16:56:47,654 [WARNING] django.request: Not Found: /
2019-01-14 16:56:48,437 [WARNING] django.request: Not Found: /rest_RSA
2019-01-14 16:56:54,492 [ERROR] django.request: Internal Server Error: /request_AES256
Traceback (most recent call last):
  File "/Volumes/Work/ddtech/aegis/employee/views.py", line 152, in request_AES256
    response = HttpResponse(json.dump(result, cls=DateTimeEncoder))
TypeError: dump() missing 1 required positional argument: 'fp'

During handling of the above exception, another exception occurred:

Traceback (most recent call last):
  File "/Volumes/Work/ddtech/ddtenv/lib/python3.6/site-packages/django/core/handlers/exception.py", line 34, in inner
    response = get_response(request)
  File "/Volumes/Work/ddtech/ddtenv/lib/python3.6/site-packages/django/core/handlers/base.py", line 126, in _get_response
    response = self.process_exception_by_middleware(e, request)
  File "/Volumes/Work/ddtech/ddtenv/lib/python3.6/site-packages/django/core/handlers/base.py", line 124, in _get_response
    response = wrapped_callback(request, *callback_args, **callback_kwargs)
  File "/Volumes/Work/ddtech/aegis/employee/views.py", line 156, in request_AES256
    eResponse = HttpResponse(json.dump({'R': 20, 'M': "에러 났어요"}))
TypeError: dump() missing 1 required positional argument: 'fp'
2019-01-14 16:56:54,545 [WARNING] django.request: Not Found: /favicon.ico
2019-01-14 16:57:08,576 [ERROR] django.request: Service Unavailable: /request_AES256
2019-01-14 16:57:54,375 [ERROR] django.request: Service Unavailable: /request_AES256
2019-01-14 17:00:53,791 [ERROR] django.request: Service Unavailable: /request_AES256
2019-01-14 17:04:48,046 [ERROR] django.request: Internal Server Error: /request_AES256
Traceback (most recent call last):
  File "/Volumes/Work/ddtech/aegis/employee/views.py", line 147, in request_AES256
    if request.method == 'POST':
NameError: name 'request' is not defined

During handling of the above exception, another exception occurred:

Traceback (most recent call last):
  File "/Volumes/Work/ddtech/ddtenv/lib/python3.6/site-packages/django/core/handlers/exception.py", line 34, in inner
    response = get_response(request)
  File "/Volumes/Work/ddtech/ddtenv/lib/python3.6/site-packages/django/core/handlers/base.py", line 126, in _get_response
    response = self.process_exception_by_middleware(e, request)
  File "/Volumes/Work/ddtech/ddtenv/lib/python3.6/site-packages/django/core/handlers/base.py", line 124, in _get_response
    response = wrapped_callback(request, *callback_args, **callback_kwargs)
  File "/Volumes/Work/ddtech/aegis/employee/views.py", line 167, in request_AES256
    return exceptionError('request_AES256', 0, e)
  File "/Volumes/Work/ddtech/aegis/employee/views.py", line 173, in exceptionError
    logError(funcName + ' >>> ' + code + ' ERROR: ' + str(e))
TypeError: must be str, not int
2019-01-14 17:05:25,998 [DEBUG] aegis.log: request_AES256 >>> 0 ERROR: name 'request' is not defined
2019-01-14 17:05:26,086 [ERROR] django.request: Internal Server Error: /request_AES256
Traceback (most recent call last):
  File "/Volumes/Work/ddtech/aegis/employee/views.py", line 147, in request_AES256
    if request.method == 'POST':
NameError: name 'request' is not defined

During handling of the above exception, another exception occurred:

Traceback (most recent call last):
  File "/Volumes/Work/ddtech/ddtenv/lib/python3.6/site-packages/django/core/handlers/exception.py", line 34, in inner
    response = get_response(request)
  File "/Volumes/Work/ddtech/ddtenv/lib/python3.6/site-packages/django/core/handlers/base.py", line 126, in _get_response
    response = self.process_exception_by_middleware(e, request)
  File "/Volumes/Work/ddtech/ddtenv/lib/python3.6/site-packages/django/core/handlers/base.py", line 124, in _get_response
    response = wrapped_callback(request, *callback_args, **callback_kwargs)
  File "/Volumes/Work/ddtech/aegis/employee/views.py", line 167, in request_AES256
    return exceptionError('request_AES256', '0', e)
  File "/Volumes/Work/ddtech/aegis/employee/views.py", line 176, in exceptionError
    return testResponse(json.dumps(result, cls=DateTimeEncoder))
NameError: name 'testResponse' is not defined
2019-01-14 17:05:45,046 [DEBUG] aegis.log: request_AES256 >>> 0 ERROR: name 'request' is not defined
2019-01-14 17:05:56,441 [DEBUG] aegis.log: request_AES256 >>> 0 ERROR: name 'request' is not defined
2019-01-14 17:06:13,687 [DEBUG] aegis.log: request_AES256 >>> 0 ERROR: 'rk'
2019-01-14 17:07:27,590 [DEBUG] aegis.log: request_AES256 >>> 0 ERROR: 'rk'
2019-01-14 17:07:53,723 [DEBUG] aegis.log: request_AES256 >>> 0 ERROR: 'rk'
2019-01-14 17:10:15,338 [ERROR] django.request: Service Unavailable: /request_AES256
2019-01-14 17:10:15,355 [WARNING] django.request: Not Found: /favicon.ico
2019-01-14 17:10:30,100 [ERROR] django.request: Service Unavailable: /request_AES256
2019-01-14 17:10:32,775 [DEBUG] aegis.log: request_AES256 >>> 0 ERROR: 'rk'
2019-01-14 17:10:33,222 [WARNING] django.request: Not Found: /
2019-01-14 17:16:40,035 [WARNING] django.request: Not Found: /
2019-01-14 17:16:44,250 [WARNING] django.request: Not Found: /
2019-01-14 17:16:44,598 [DEBUG] aegis.log: request_AES256 >>> 0 ERROR: 'rk'
2019-01-14 17:16:47,484 [ERROR] django.request: Service Unavailable: /request_AES256
2019-01-14 17:16:50,317 [ERROR] django.request: Service Unavailable: /request_AES256
2019-01-14 17:17:43,339 [ERROR] django.request: Service Unavailable: /request_AES256
2019-01-14 17:31:08,605 [ERROR] django.request: Service Unavailable: /request_AES256
2019-01-14 17:31:21,251 [DEBUG] aegis.log: request_AES256 >>> 0 ERROR: 'rk'
2019-01-14 17:48:48,961 [ERROR] django.request: Service Unavailable: /request_AES256
2019-01-14 17:52:24,256 [ERROR] django.request: Service Unavailable: /request_AES256
2019-01-14 17:52:56,281 [ERROR] django.request: Service Unavailable: /request_AES256
2019-01-14 17:53:36,677 [ERROR] django.request: Service Unavailable: /request_AES256
2019-01-14 17:53:36,705 [WARNING] django.request: Not Found: /favicon.ico
2019-01-14 17:53:54,893 [DEBUG] aegis.log: request_AES256 >>> 0 ERROR: 'rk'
2019-01-14 17:54:53,112 [DEBUG] aegis.log: request_AES256 >>> 0 ERROR: 'rk'
2019-01-14 17:55:02,110 [DEBUG] aegis.log: request_AES256 >>> 0 ERROR: 'rk'
2019-01-14 17:57:12,906 [DEBUG] aegis.log: request_AES256 >>> 0 ERROR: 'rk'
2019-01-14 17:57:25,514 [DEBUG] aegis.log: request_AES256 >>> 0 ERROR: 'rk'
2019-01-14 17:58:20,732 [DEBUG] aegis.log: request_AES256 >>> 0 ERROR: 'rk'
2019-01-15 15:23:36,871 [WARNING] django.request: Bad Request: /
2019-01-15 15:23:36,985 [WARNING] django.request: Bad Request: /favicon.ico
2019-01-15 15:23:46,247 [WARNING] django.request: Not Found: /
2019-01-15 15:23:49,851 [WARNING] django.request: Not Found: /
2019-01-15 15:23:56,867 [WARNING] django.request: Not Found: /
2019-01-15 15:23:58,880 [WARNING] django.request: Not Found: /favicon.ico
2019-01-15 15:25:03,114 [WARNING] django.request: Not Found: /
2019-01-15 15:25:03,143 [WARNING] django.request: Not Found: /favicon.ico
2019-01-15 15:25:07,229 [WARNING] django.request: Not Found: /
2019-01-15 15:25:16,299 [WARNING] django.request: Not Found: /
2019-01-15 15:25:16,327 [WARNING] django.request: Not Found: /favicon.ico
2019-01-15 15:25:19,095 [WARNING] django.request: Not Found: /
2019-01-15 15:25:22,170 [WARNING] django.request: Not Found: /favicon.ico
2019-01-15 15:27:10,394 [WARNING] django.request: Bad Request: /swagger
2019-01-15 15:27:10,508 [WARNING] django.request: Bad Request: /favicon.ico
2019-01-15 16:53:13,656 [WARNING] django.request: Bad Request: /swagger
2019-01-15 16:53:13,772 [WARNING] django.request: Bad Request: /favicon.ico
2019-01-16 01:21:27,794 [WARNING] django.request: Not Found: /
2019-01-16 01:21:27,826 [WARNING] django.request: Not Found: /favicon.ico
2019-01-16 01:21:36,351 [DEBUG] aegis.log: >>> testEncryptionStr: 
2019-01-16 01:21:36,412 [ERROR] django.request: Internal Server Error: /testEncryptionStr
Traceback (most recent call last):
  File "/Volumes/Work/ddtech/ddtenv/lib/python3.6/site-packages/django/core/handlers/exception.py", line 34, in inner
    response = get_response(request)
  File "/Volumes/Work/ddtech/ddtenv/lib/python3.6/site-packages/django/core/handlers/base.py", line 126, in _get_response
    response = self.process_exception_by_middleware(e, request)
  File "/Volumes/Work/ddtech/ddtenv/lib/python3.6/site-packages/django/core/handlers/base.py", line 124, in _get_response
    response = wrapped_callback(request, *callback_args, **callback_kwargs)
  File "/Volumes/Work/ddtech/ddtenv/lib/python3.6/site-packages/django/views/decorators/csrf.py", line 54, in wrapped_view
    return view_func(*args, **kwargs)
  File "/Volumes/Work/ddtech/aegis/config/secret.py", line 96, in testEncryptionStr
    logSend(_plainText.decode('utf-8'))
AttributeError: 'str' object has no attribute 'decode'
2019-01-16 01:21:36,495 [WARNING] django.request: Not Found: /favicon.ico
2019-01-16 01:22:35,592 [DEBUG] aegis.log: >>> testEncryptionStr: 1234567890ABCDEFGHIJKLMNOPQRSTUVWXYZ%20%EA%B0%80%EB%82%98%EB%8B%A4%EB%9D%BC%EB%A7%88%EB%B0%94%EC%82%AC%EC%95%84%EC%9E%90%EC%B0%A8%EC%B9%B4%ED%83%80%ED%8C%8C%ED%95%98
2019-01-16 01:22:35,621 [ERROR] django.request: Internal Server Error: /testEncryptionStr
Traceback (most recent call last):
  File "/Volumes/Work/ddtech/ddtenv/lib/python3.6/site-packages/django/core/handlers/exception.py", line 34, in inner
    response = get_response(request)
  File "/Volumes/Work/ddtech/ddtenv/lib/python3.6/site-packages/django/core/handlers/base.py", line 126, in _get_response
    response = self.process_exception_by_middleware(e, request)
  File "/Volumes/Work/ddtech/ddtenv/lib/python3.6/site-packages/django/core/handlers/base.py", line 124, in _get_response
    response = wrapped_callback(request, *callback_args, **callback_kwargs)
  File "/Volumes/Work/ddtech/ddtenv/lib/python3.6/site-packages/django/views/decorators/csrf.py", line 54, in wrapped_view
    return view_func(*args, **kwargs)
  File "/Volumes/Work/ddtech/aegis/config/secret.py", line 96, in testEncryptionStr
    logSend(_plainText.decode('utf-8'))
AttributeError: 'str' object has no attribute 'decode'
2019-01-16 01:22:35,718 [WARNING] django.request: Not Found: /favicon.ico
2019-01-16 01:26:09,247 [DEBUG] aegis.log: >>> testEncryptionStr: 1234567890ABCDEFGHIJKLMNOPQRSTUVWXYZ%20%EA%B0%80%EB%82%98%EB%8B%A4%EB%9D%BC%EB%A7%88%EB%B0%94%EC%82%AC%EC%95%84%EC%9E%90%EC%B0%A8%EC%B9%B4%ED%83%80%ED%8C%8C%ED%95%98
2019-01-16 01:26:09,248 [DEBUG] aegis.log: 1234567890ABCDEFGHIJKLMNOPQRSTUVWXYZ%20%EA%B0%80%EB%82%98%EB%8B%A4%EB%9D%BC%EB%A7%88%EB%B0%94%EC%82%AC%EC%95%84%EC%9E%90%EC%B0%A8%EC%B9%B4%ED%83%80%ED%8C%8C%ED%95%98
2019-01-16 01:26:09,313 [ERROR] django.request: Internal Server Error: /testEncryptionStr
Traceback (most recent call last):
  File "/Volumes/Work/ddtech/ddtenv/lib/python3.6/site-packages/django/core/handlers/exception.py", line 34, in inner
    response = get_response(request)
  File "/Volumes/Work/ddtech/ddtenv/lib/python3.6/site-packages/django/core/handlers/base.py", line 126, in _get_response
    response = self.process_exception_by_middleware(e, request)
  File "/Volumes/Work/ddtech/ddtenv/lib/python3.6/site-packages/django/core/handlers/base.py", line 124, in _get_response
    response = wrapped_callback(request, *callback_args, **callback_kwargs)
  File "/Volumes/Work/ddtech/ddtenv/lib/python3.6/site-packages/django/views/decorators/csrf.py", line 54, in wrapped_view
    return view_func(*args, **kwargs)
  File "/Volumes/Work/ddtech/aegis/config/secret.py", line 99, in testEncryptionStr
    _cipherText = AES_ENCRYPT(_plainText)
  File "/Volumes/Work/ddtech/aegis/config/secret.py", line 23, in AES_ENCRYPT
    aes = AES.new(bytes(AESkey), AES.MODE_CBC, AESiv)
TypeError: string argument without an encoding
2019-01-16 01:27:10,871 [DEBUG] aegis.log: >>> testEncryptionStr: 
2019-01-16 01:27:10,871 [DEBUG] aegis.log: 
2019-01-16 01:27:10,901 [ERROR] django.request: Internal Server Error: /testEncryptionStr
Traceback (most recent call last):
  File "/Volumes/Work/ddtech/ddtenv/lib/python3.6/site-packages/django/core/handlers/exception.py", line 34, in inner
    response = get_response(request)
  File "/Volumes/Work/ddtech/ddtenv/lib/python3.6/site-packages/django/core/handlers/base.py", line 126, in _get_response
    response = self.process_exception_by_middleware(e, request)
  File "/Volumes/Work/ddtech/ddtenv/lib/python3.6/site-packages/django/core/handlers/base.py", line 124, in _get_response
    response = wrapped_callback(request, *callback_args, **callback_kwargs)
  File "/Volumes/Work/ddtech/ddtenv/lib/python3.6/site-packages/django/views/decorators/csrf.py", line 54, in wrapped_view
    return view_func(*args, **kwargs)
  File "/Volumes/Work/ddtech/aegis/config/secret.py", line 99, in testEncryptionStr
    _cipherText = AES_ENCRYPT(_plainText)
  File "/Volumes/Work/ddtech/aegis/config/secret.py", line 23, in AES_ENCRYPT
    aes = AES.new(bytes(AESkey), AES.MODE_CBC, AESiv)
TypeError: string argument without an encoding
2019-01-16 01:29:17,521 [DEBUG] aegis.log: >>> testEncryptionStr: 1234567890ABCDEFGHIJKLMNOPQRSTUVWXYZ%20%EA%B0%80%EB%82%98%EB%8B%A4%EB%9D%BC%EB%A7%88%EB%B0%94%EC%82%AC%EC%95%84%EC%9E%90%EC%B0%A8%EC%B9%B4%ED%83%80%ED%8C%8C%ED%95%98
2019-01-16 01:29:17,521 [DEBUG] aegis.log: 1234567890ABCDEFGHIJKLMNOPQRSTUVWXYZ%20%EA%B0%80%EB%82%98%EB%8B%A4%EB%9D%BC%EB%A7%88%EB%B0%94%EC%82%AC%EC%95%84%EC%9E%90%EC%B0%A8%EC%B9%B4%ED%83%80%ED%8C%8C%ED%95%98
2019-01-16 01:29:17,585 [ERROR] django.request: Internal Server Error: /testEncryptionStr
Traceback (most recent call last):
  File "/Volumes/Work/ddtech/ddtenv/lib/python3.6/site-packages/django/core/handlers/exception.py", line 34, in inner
    response = get_response(request)
  File "/Volumes/Work/ddtech/ddtenv/lib/python3.6/site-packages/django/core/handlers/base.py", line 126, in _get_response
    response = self.process_exception_by_middleware(e, request)
  File "/Volumes/Work/ddtech/ddtenv/lib/python3.6/site-packages/django/core/handlers/base.py", line 124, in _get_response
    response = wrapped_callback(request, *callback_args, **callback_kwargs)
  File "/Volumes/Work/ddtech/ddtenv/lib/python3.6/site-packages/django/views/decorators/csrf.py", line 54, in wrapped_view
    return view_func(*args, **kwargs)
  File "/Volumes/Work/ddtech/aegis/config/secret.py", line 101, in testEncryptionStr
    r += '</br>*** cipherText(bytes) = ' + AES_ENCRYPT_HEX(_cipherText)
  File "/Volumes/Work/ddtech/aegis/config/secret.py", line 37, in AES_ENCRYPT_HEX
    cipherText = AES_ENCRYPT(msg)
  File "/Volumes/Work/ddtech/aegis/config/secret.py", line 29, in AES_ENCRYPT
    return aes.encrypt(msg2)
  File "/Volumes/Work/ddtech/ddtenv/lib/python3.6/site-packages/Crypto/Cipher/blockalgo.py", line 244, in encrypt
    return self._cipher.encrypt(plaintext)
ValueError: Input strings must be a multiple of 16 in length
2019-01-16 01:31:55,580 [DEBUG] aegis.log: >>> testEncryptionStr: 1234567890ABCDEFGHIJKLMNOPQRSTUVWXYZ%20%EA%B0%80%EB%82%98%EB%8B%A4%EB%9D%BC%EB%A7%88%EB%B0%94%EC%82%AC%EC%95%84%EC%9E%90%EC%B0%A8%EC%B9%B4%ED%83%80%ED%8C%8C%ED%95%98
2019-01-16 01:31:55,581 [DEBUG] aegis.log: 1234567890ABCDEFGHIJKLMNOPQRSTUVWXYZ%20%EA%B0%80%EB%82%98%EB%8B%A4%EB%9D%BC%EB%A7%88%EB%B0%94%EC%82%AC%EC%95%84%EC%9E%90%EC%B0%A8%EC%B9%B4%ED%83%80%ED%8C%8C%ED%95%98
2019-01-16 01:31:55,644 [ERROR] django.request: Internal Server Error: /testEncryptionStr
Traceback (most recent call last):
  File "/Volumes/Work/ddtech/ddtenv/lib/python3.6/site-packages/django/core/handlers/exception.py", line 34, in inner
    response = get_response(request)
  File "/Volumes/Work/ddtech/ddtenv/lib/python3.6/site-packages/django/core/handlers/base.py", line 126, in _get_response
    response = self.process_exception_by_middleware(e, request)
  File "/Volumes/Work/ddtech/ddtenv/lib/python3.6/site-packages/django/core/handlers/base.py", line 124, in _get_response
    response = wrapped_callback(request, *callback_args, **callback_kwargs)
  File "/Volumes/Work/ddtech/ddtenv/lib/python3.6/site-packages/django/views/decorators/csrf.py", line 54, in wrapped_view
    return view_func(*args, **kwargs)
  File "/Volumes/Work/ddtech/aegis/config/secret.py", line 100, in testEncryptionStr
    _cipherText = AES_ENCRYPT(_plainText)
  File "/Volumes/Work/ddtech/aegis/config/secret.py", line 24, in AES_ENCRYPT
    aes = AES.new(AESkey, AES.MODE_EAX, AESiv)
AttributeError: module 'Crypto.Cipher.AES' has no attribute 'MODE_EAX'
2019-01-16 01:34:41,811 [DEBUG] aegis.log: >>> testEncryptionStr: 1234567890ABCDEFGHIJKLMNOPQRSTUVWXYZ%20%EA%B0%80%EB%82%98%EB%8B%A4%EB%9D%BC%EB%A7%88%EB%B0%94%EC%82%AC%EC%95%84%EC%9E%90%EC%B0%A8%EC%B9%B4%ED%83%80%ED%8C%8C%ED%95%98
2019-01-16 01:34:41,812 [DEBUG] aegis.log: 1234567890ABCDEFGHIJKLMNOPQRSTUVWXYZ%20%EA%B0%80%EB%82%98%EB%8B%A4%EB%9D%BC%EB%A7%88%EB%B0%94%EC%82%AC%EC%95%84%EC%9E%90%EC%B0%A8%EC%B9%B4%ED%83%80%ED%8C%8C%ED%95%98
2019-01-16 01:34:41,880 [ERROR] django.request: Internal Server Error: /testEncryptionStr
Traceback (most recent call last):
  File "/Volumes/Work/ddtech/ddtenv/lib/python3.6/site-packages/django/core/handlers/exception.py", line 34, in inner
    response = get_response(request)
  File "/Volumes/Work/ddtech/ddtenv/lib/python3.6/site-packages/django/core/handlers/base.py", line 126, in _get_response
    response = self.process_exception_by_middleware(e, request)
  File "/Volumes/Work/ddtech/ddtenv/lib/python3.6/site-packages/django/core/handlers/base.py", line 124, in _get_response
    response = wrapped_callback(request, *callback_args, **callback_kwargs)
  File "/Volumes/Work/ddtech/ddtenv/lib/python3.6/site-packages/django/views/decorators/csrf.py", line 54, in wrapped_view
    return view_func(*args, **kwargs)
  File "/Volumes/Work/ddtech/aegis/config/secret.py", line 101, in testEncryptionStr
    r += '</br>*** cipherText(bytes) = ' + AES_ENCRYPT_HEX(_cipherText)
  File "/Volumes/Work/ddtech/aegis/config/secret.py", line 37, in AES_ENCRYPT_HEX
    cipherText = AES_ENCRYPT(msg)
  File "/Volumes/Work/ddtech/aegis/config/secret.py", line 29, in AES_ENCRYPT
    return aes.encrypt(msg2)
  File "/Volumes/Work/ddtech/ddtenv/lib/python3.6/site-packages/Crypto/Cipher/blockalgo.py", line 244, in encrypt
    return self._cipher.encrypt(plaintext)
ValueError: Input strings must be a multiple of 16 in length
2019-01-16 01:36:57,158 [DEBUG] aegis.log: >>> testEncryptionStr: 1234567890ABCDEFGHIJKLMNOPQRSTUVWXYZ%20%EA%B0%80%EB%82%98%EB%8B%A4%EB%9D%BC%EB%A7%88%EB%B0%94%EC%82%AC%EC%95%84%EC%9E%90%EC%B0%A8%EC%B9%B4%ED%83%80%ED%8C%8C%ED%95%98
2019-01-16 01:36:57,158 [DEBUG] aegis.log: 1234567890ABCDEFGHIJKLMNOPQRSTUVWXYZ%20%EA%B0%80%EB%82%98%EB%8B%A4%EB%9D%BC%EB%A7%88%EB%B0%94%EC%82%AC%EC%95%84%EC%9E%90%EC%B0%A8%EC%B9%B4%ED%83%80%ED%8C%8C%ED%95%98
2019-01-16 01:36:57,222 [ERROR] django.request: Internal Server Error: /testEncryptionStr
Traceback (most recent call last):
  File "/Volumes/Work/ddtech/ddtenv/lib/python3.6/site-packages/django/core/handlers/exception.py", line 34, in inner
    response = get_response(request)
  File "/Volumes/Work/ddtech/ddtenv/lib/python3.6/site-packages/django/core/handlers/base.py", line 126, in _get_response
    response = self.process_exception_by_middleware(e, request)
  File "/Volumes/Work/ddtech/ddtenv/lib/python3.6/site-packages/django/core/handlers/base.py", line 124, in _get_response
    response = wrapped_callback(request, *callback_args, **callback_kwargs)
  File "/Volumes/Work/ddtech/ddtenv/lib/python3.6/site-packages/django/views/decorators/csrf.py", line 54, in wrapped_view
    return view_func(*args, **kwargs)
  File "/Volumes/Work/ddtech/aegis/config/secret.py", line 102, in testEncryptionStr
    r += '</br>*** cipherText(bytes) = ' + AES_ENCRYPT_HEX(_cipherText)
  File "/Volumes/Work/ddtech/aegis/config/secret.py", line 38, in AES_ENCRYPT_HEX
    cipherText = AES_ENCRYPT(msg)
  File "/Volumes/Work/ddtech/aegis/config/secret.py", line 30, in AES_ENCRYPT
    return aes.encrypt(msg2)
  File "/Volumes/Work/ddtech/ddtenv/lib/python3.6/site-packages/Crypto/Cipher/blockalgo.py", line 244, in encrypt
    return self._cipher.encrypt(plaintext)
ValueError: Input strings must be a multiple of 16 in length
2019-01-16 01:37:35,970 [DEBUG] aegis.log: >>> testEncryptionStr: 1234567890ABCDEFGHIJKLMNOPQRSTUVWXYZ%20%EA%B0%80%EB%82%98%EB%8B%A4%EB%9D%BC%EB%A7%88%EB%B0%94%EC%82%AC%EC%95%84%EC%9E%90%EC%B0%A8%EC%B9%B4%ED%83%80%ED%8C%8C%ED%95%98
2019-01-16 01:37:35,971 [DEBUG] aegis.log: 1234567890ABCDEFGHIJKLMNOPQRSTUVWXYZ%20%EA%B0%80%EB%82%98%EB%8B%A4%EB%9D%BC%EB%A7%88%EB%B0%94%EC%82%AC%EC%95%84%EC%9E%90%EC%B0%A8%EC%B9%B4%ED%83%80%ED%8C%8C%ED%95%98
2019-01-16 01:37:36,034 [ERROR] django.request: Internal Server Error: /testEncryptionStr
Traceback (most recent call last):
  File "/Volumes/Work/ddtech/ddtenv/lib/python3.6/site-packages/django/core/handlers/exception.py", line 34, in inner
    response = get_response(request)
  File "/Volumes/Work/ddtech/ddtenv/lib/python3.6/site-packages/django/core/handlers/base.py", line 126, in _get_response
    response = self.process_exception_by_middleware(e, request)
  File "/Volumes/Work/ddtech/ddtenv/lib/python3.6/site-packages/django/core/handlers/base.py", line 124, in _get_response
    response = wrapped_callback(request, *callback_args, **callback_kwargs)
  File "/Volumes/Work/ddtech/ddtenv/lib/python3.6/site-packages/django/views/decorators/csrf.py", line 54, in wrapped_view
    return view_func(*args, **kwargs)
  File "/Volumes/Work/ddtech/aegis/config/secret.py", line 102, in testEncryptionStr
    r += '</br>*** cipherText(bytes) = ' + AES_ENCRYPT_HEX(_cipherText)
  File "/Volumes/Work/ddtech/aegis/config/secret.py", line 38, in AES_ENCRYPT_HEX
    cipherText = AES_ENCRYPT(msg)
  File "/Volumes/Work/ddtech/aegis/config/secret.py", line 30, in AES_ENCRYPT
    return aes.encrypt(msg2)
  File "/Volumes/Work/ddtech/ddtenv/lib/python3.6/site-packages/Crypto/Cipher/blockalgo.py", line 244, in encrypt
    return self._cipher.encrypt(plaintext)
ValueError: Input strings must be a multiple of 16 in length
2019-01-16 01:48:33,107 [DEBUG] aegis.log: >>> testEncryptionStr: 1234567890ABCDEFGHIJKLMNOPQRSTUVWXYZ%20%EA%B0%80%EB%82%98%EB%8B%A4%EB%9D%BC%EB%A7%88%EB%B0%94%EC%82%AC%EC%95%84%EC%9E%90%EC%B0%A8%EC%B9%B4%ED%83%80%ED%8C%8C%ED%95%98
2019-01-16 01:48:33,107 [DEBUG] aegis.log: 1234567890ABCDEFGHIJKLMNOPQRSTUVWXYZ%20%EA%B0%80%EB%82%98%EB%8B%A4%EB%9D%BC%EB%A7%88%EB%B0%94%EC%82%AC%EC%95%84%EC%9E%90%EC%B0%A8%EC%B9%B4%ED%83%80%ED%8C%8C%ED%95%98
2019-01-16 01:48:33,173 [ERROR] django.request: Internal Server Error: /testEncryptionStr
Traceback (most recent call last):
  File "/Volumes/Work/ddtech/ddtenv/lib/python3.6/site-packages/django/core/handlers/exception.py", line 34, in inner
    response = get_response(request)
  File "/Volumes/Work/ddtech/ddtenv/lib/python3.6/site-packages/django/core/handlers/base.py", line 126, in _get_response
    response = self.process_exception_by_middleware(e, request)
  File "/Volumes/Work/ddtech/ddtenv/lib/python3.6/site-packages/django/core/handlers/base.py", line 124, in _get_response
    response = wrapped_callback(request, *callback_args, **callback_kwargs)
  File "/Volumes/Work/ddtech/ddtenv/lib/python3.6/site-packages/django/views/decorators/csrf.py", line 54, in wrapped_view
    return view_func(*args, **kwargs)
  File "/Volumes/Work/ddtech/aegis/config/secret.py", line 128, in testEncryptionStr
    _cipherText = AES_ENCRYPT(_plainText)
  File "/Volumes/Work/ddtech/aegis/config/secret.py", line 55, in AES_ENCRYPT
    msg2 = pad(bytes(msg), 16)
TypeError: string argument without an encoding
2019-01-16 01:50:09,464 [DEBUG] aegis.log: >>> testEncryptionStr: 1234567890ABCDEFGHIJKLMNOPQRSTUVWXYZ%20%EA%B0%80%EB%82%98%EB%8B%A4%EB%9D%BC%EB%A7%88%EB%B0%94%EC%82%AC%EC%95%84%EC%9E%90%EC%B0%A8%EC%B9%B4%ED%83%80%ED%8C%8C%ED%95%98
2019-01-16 01:50:09,464 [DEBUG] aegis.log: 1234567890ABCDEFGHIJKLMNOPQRSTUVWXYZ%20%EA%B0%80%EB%82%98%EB%8B%A4%EB%9D%BC%EB%A7%88%EB%B0%94%EC%82%AC%EC%95%84%EC%9E%90%EC%B0%A8%EC%B9%B4%ED%83%80%ED%8C%8C%ED%95%98
2019-01-16 01:50:09,525 [ERROR] django.request: Internal Server Error: /testEncryptionStr
Traceback (most recent call last):
  File "/Volumes/Work/ddtech/ddtenv/lib/python3.6/site-packages/django/core/handlers/exception.py", line 34, in inner
    response = get_response(request)
  File "/Volumes/Work/ddtech/ddtenv/lib/python3.6/site-packages/django/core/handlers/base.py", line 126, in _get_response
    response = self.process_exception_by_middleware(e, request)
  File "/Volumes/Work/ddtech/ddtenv/lib/python3.6/site-packages/django/core/handlers/base.py", line 124, in _get_response
    response = wrapped_callback(request, *callback_args, **callback_kwargs)
  File "/Volumes/Work/ddtech/ddtenv/lib/python3.6/site-packages/django/views/decorators/csrf.py", line 54, in wrapped_view
    return view_func(*args, **kwargs)
  File "/Volumes/Work/ddtech/aegis/config/secret.py", line 128, in testEncryptionStr
    _cipherText = AES_ENCRYPT(_plainText)
  File "/Volumes/Work/ddtech/aegis/config/secret.py", line 55, in AES_ENCRYPT
    msg2 = pad(bytes(msg), 16)
TypeError: string argument without an encoding
2019-01-16 01:50:25,817 [DEBUG] aegis.log: >>> testEncryptionStr: 1234567890ABCDEFGHIJKLMNOPQRSTUVWXYZ%20%EA%B0%80%EB%82%98%EB%8B%A4%EB%9D%BC%EB%A7%88%EB%B0%94%EC%82%AC%EC%95%84%EC%9E%90%EC%B0%A8%EC%B9%B4%ED%83%80%ED%8C%8C%ED%95%98
2019-01-16 01:50:25,817 [DEBUG] aegis.log: 1234567890ABCDEFGHIJKLMNOPQRSTUVWXYZ%20%EA%B0%80%EB%82%98%EB%8B%A4%EB%9D%BC%EB%A7%88%EB%B0%94%EC%82%AC%EC%95%84%EC%9E%90%EC%B0%A8%EC%B9%B4%ED%83%80%ED%8C%8C%ED%95%98
2019-01-16 01:50:25,847 [ERROR] django.request: Internal Server Error: /testEncryptionStr
Traceback (most recent call last):
  File "/Volumes/Work/ddtech/ddtenv/lib/python3.6/site-packages/django/core/handlers/exception.py", line 34, in inner
    response = get_response(request)
  File "/Volumes/Work/ddtech/ddtenv/lib/python3.6/site-packages/django/core/handlers/base.py", line 126, in _get_response
    response = self.process_exception_by_middleware(e, request)
  File "/Volumes/Work/ddtech/ddtenv/lib/python3.6/site-packages/django/core/handlers/base.py", line 124, in _get_response
    response = wrapped_callback(request, *callback_args, **callback_kwargs)
  File "/Volumes/Work/ddtech/ddtenv/lib/python3.6/site-packages/django/views/decorators/csrf.py", line 54, in wrapped_view
    return view_func(*args, **kwargs)
  File "/Volumes/Work/ddtech/aegis/config/secret.py", line 128, in testEncryptionStr
    _cipherText = AES_ENCRYPT(_plainText)
  File "/Volumes/Work/ddtech/aegis/config/secret.py", line 55, in AES_ENCRYPT
    msg2 = pad(bytes(msg), 16)
TypeError: string argument without an encoding
2019-01-16 01:51:17,256 [DEBUG] aegis.log: >>> testEncryptionStr: 1234567890ABCDEFGHIJKLMNOPQRSTUVWXYZ%20%EA%B0%80%EB%82%98%EB%8B%A4%EB%9D%BC%EB%A7%88%EB%B0%94%EC%82%AC%EC%95%84%EC%9E%90%EC%B0%A8%EC%B9%B4%ED%83%80%ED%8C%8C%ED%95%98
2019-01-16 01:51:17,256 [DEBUG] aegis.log: 1234567890ABCDEFGHIJKLMNOPQRSTUVWXYZ%20%EA%B0%80%EB%82%98%EB%8B%A4%EB%9D%BC%EB%A7%88%EB%B0%94%EC%82%AC%EC%95%84%EC%9E%90%EC%B0%A8%EC%B9%B4%ED%83%80%ED%8C%8C%ED%95%98
2019-01-16 01:51:17,318 [ERROR] django.request: Internal Server Error: /testEncryptionStr
Traceback (most recent call last):
  File "/Volumes/Work/ddtech/ddtenv/lib/python3.6/site-packages/django/core/handlers/exception.py", line 34, in inner
    response = get_response(request)
  File "/Volumes/Work/ddtech/ddtenv/lib/python3.6/site-packages/django/core/handlers/base.py", line 126, in _get_response
    response = self.process_exception_by_middleware(e, request)
  File "/Volumes/Work/ddtech/ddtenv/lib/python3.6/site-packages/django/core/handlers/base.py", line 124, in _get_response
    response = wrapped_callback(request, *callback_args, **callback_kwargs)
  File "/Volumes/Work/ddtech/ddtenv/lib/python3.6/site-packages/django/views/decorators/csrf.py", line 54, in wrapped_view
    return view_func(*args, **kwargs)
  File "/Volumes/Work/ddtech/aegis/config/secret.py", line 128, in testEncryptionStr
    _cipherText = AES_ENCRYPT(_plainText)
  File "/Volumes/Work/ddtech/aegis/config/secret.py", line 55, in AES_ENCRYPT
    msg2 = pad(bytes(msg), 16, 'pkcs7')
TypeError: string argument without an encoding
2019-01-16 01:52:18,636 [DEBUG] aegis.log: >>> testEncryptionStr: 1234567890ABCDEFGHIJKLMNOPQRSTUVWXYZ%20%EA%B0%80%EB%82%98%EB%8B%A4%EB%9D%BC%EB%A7%88%EB%B0%94%EC%82%AC%EC%95%84%EC%9E%90%EC%B0%A8%EC%B9%B4%ED%83%80%ED%8C%8C%ED%95%98
2019-01-16 01:52:18,636 [DEBUG] aegis.log: 1234567890ABCDEFGHIJKLMNOPQRSTUVWXYZ%20%EA%B0%80%EB%82%98%EB%8B%A4%EB%9D%BC%EB%A7%88%EB%B0%94%EC%82%AC%EC%95%84%EC%9E%90%EC%B0%A8%EC%B9%B4%ED%83%80%ED%8C%8C%ED%95%98
2019-01-16 01:52:18,704 [ERROR] django.request: Internal Server Error: /testEncryptionStr
Traceback (most recent call last):
  File "/Volumes/Work/ddtech/ddtenv/lib/python3.6/site-packages/django/core/handlers/exception.py", line 34, in inner
    response = get_response(request)
  File "/Volumes/Work/ddtech/ddtenv/lib/python3.6/site-packages/django/core/handlers/base.py", line 126, in _get_response
    response = self.process_exception_by_middleware(e, request)
  File "/Volumes/Work/ddtech/ddtenv/lib/python3.6/site-packages/django/core/handlers/base.py", line 124, in _get_response
    response = wrapped_callback(request, *callback_args, **callback_kwargs)
  File "/Volumes/Work/ddtech/ddtenv/lib/python3.6/site-packages/django/views/decorators/csrf.py", line 54, in wrapped_view
    return view_func(*args, **kwargs)
  File "/Volumes/Work/ddtech/aegis/config/secret.py", line 129, in testEncryptionStr
    r += '</br>*** cipherText(bytes) = ' + AES_ENCRYPT_HEX(_cipherText)
  File "/Volumes/Work/ddtech/aegis/config/secret.py", line 65, in AES_ENCRYPT_HEX
    cipherText = AES_ENCRYPT(msg)
  File "/Volumes/Work/ddtech/aegis/config/secret.py", line 55, in AES_ENCRYPT
    msg2 = pad(bytes(msg, 'utf-8'), 16, 'pkcs7')
TypeError: encoding without a string argument
2019-01-16 01:55:30,146 [DEBUG] aegis.log: >>> testEncryptionStr: 1234567890ABCDEFGHIJKLMNOPQRSTUVWXYZ%20%EA%B0%80%EB%82%98%EB%8B%A4%EB%9D%BC%EB%A7%88%EB%B0%94%EC%82%AC%EC%95%84%EC%9E%90%EC%B0%A8%EC%B9%B4%ED%83%80%ED%8C%8C%ED%95%98
2019-01-16 01:55:30,146 [DEBUG] aegis.log: 1234567890ABCDEFGHIJKLMNOPQRSTUVWXYZ%20%EA%B0%80%EB%82%98%EB%8B%A4%EB%9D%BC%EB%A7%88%EB%B0%94%EC%82%AC%EC%95%84%EC%9E%90%EC%B0%A8%EC%B9%B4%ED%83%80%ED%8C%8C%ED%95%98
2019-01-16 01:55:30,208 [ERROR] django.request: Internal Server Error: /testEncryptionStr
Traceback (most recent call last):
  File "/Volumes/Work/ddtech/ddtenv/lib/python3.6/site-packages/django/core/handlers/exception.py", line 34, in inner
    response = get_response(request)
  File "/Volumes/Work/ddtech/ddtenv/lib/python3.6/site-packages/django/core/handlers/base.py", line 126, in _get_response
    response = self.process_exception_by_middleware(e, request)
  File "/Volumes/Work/ddtech/ddtenv/lib/python3.6/site-packages/django/core/handlers/base.py", line 124, in _get_response
    response = wrapped_callback(request, *callback_args, **callback_kwargs)
  File "/Volumes/Work/ddtech/ddtenv/lib/python3.6/site-packages/django/views/decorators/csrf.py", line 54, in wrapped_view
    return view_func(*args, **kwargs)
  File "/Volumes/Work/ddtech/aegis/config/secret.py", line 129, in testEncryptionStr
    r += '</br>*** cipherText(bytes) = ' + AES_ENCRYPT_HEX(_cipherText)
  File "/Volumes/Work/ddtech/aegis/config/secret.py", line 65, in AES_ENCRYPT_HEX
    cipherText = AES_ENCRYPT(msg)
  File "/Volumes/Work/ddtech/aegis/config/secret.py", line 55, in AES_ENCRYPT
    msg2 = pad(bytes(msg, encoding='UTF-8'), 16, 'pkcs7')
TypeError: encoding without a string argument
2019-01-16 01:56:19,747 [DEBUG] aegis.log: >>> testEncryptionStr: 1234567890ABCDEFGHIJKLMNOPQRSTUVWXYZ%20%EA%B0%80%EB%82%98%EB%8B%A4%EB%9D%BC%EB%A7%88%EB%B0%94%EC%82%AC%EC%95%84%EC%9E%90%EC%B0%A8%EC%B9%B4%ED%83%80%ED%8C%8C%ED%95%98
2019-01-16 01:56:19,747 [DEBUG] aegis.log: 1234567890ABCDEFGHIJKLMNOPQRSTUVWXYZ%20%EA%B0%80%EB%82%98%EB%8B%A4%EB%9D%BC%EB%A7%88%EB%B0%94%EC%82%AC%EC%95%84%EC%9E%90%EC%B0%A8%EC%B9%B4%ED%83%80%ED%8C%8C%ED%95%98
2019-01-16 01:56:19,833 [ERROR] django.request: Internal Server Error: /testEncryptionStr
Traceback (most recent call last):
  File "/Volumes/Work/ddtech/ddtenv/lib/python3.6/site-packages/django/core/handlers/exception.py", line 34, in inner
    response = get_response(request)
  File "/Volumes/Work/ddtech/ddtenv/lib/python3.6/site-packages/django/core/handlers/base.py", line 126, in _get_response
    response = self.process_exception_by_middleware(e, request)
  File "/Volumes/Work/ddtech/ddtenv/lib/python3.6/site-packages/django/core/handlers/base.py", line 124, in _get_response
    response = wrapped_callback(request, *callback_args, **callback_kwargs)
  File "/Volumes/Work/ddtech/ddtenv/lib/python3.6/site-packages/django/views/decorators/csrf.py", line 54, in wrapped_view
    return view_func(*args, **kwargs)
  File "/Volumes/Work/ddtech/aegis/config/secret.py", line 129, in testEncryptionStr
    r += '</br>*** cipherText(bytes) = ' + AES_ENCRYPT_HEX(_cipherText)
  File "/Volumes/Work/ddtech/aegis/config/secret.py", line 65, in AES_ENCRYPT_HEX
    cipherText = AES_ENCRYPT(msg)
  File "/Volumes/Work/ddtech/aegis/config/secret.py", line 55, in AES_ENCRYPT
    msg2 = pad(msg.encode(encoding='UTF-8'), 16, 'pkcs7')
AttributeError: 'bytes' object has no attribute 'encode'
2019-01-16 01:58:19,661 [DEBUG] aegis.log: >>> testEncryptionStr: 1234567890ABCDEFGHIJKLMNOPQRSTUVWXYZ%20%EA%B0%80%EB%82%98%EB%8B%A4%EB%9D%BC%EB%A7%88%EB%B0%94%EC%82%AC%EC%95%84%EC%9E%90%EC%B0%A8%EC%B9%B4%ED%83%80%ED%8C%8C%ED%95%98
2019-01-16 01:58:19,661 [DEBUG] aegis.log: 1234567890ABCDEFGHIJKLMNOPQRSTUVWXYZ%20%EA%B0%80%EB%82%98%EB%8B%A4%EB%9D%BC%EB%A7%88%EB%B0%94%EC%82%AC%EC%95%84%EC%9E%90%EC%B0%A8%EC%B9%B4%ED%83%80%ED%8C%8C%ED%95%98
2019-01-16 01:58:19,724 [ERROR] django.request: Internal Server Error: /testEncryptionStr
Traceback (most recent call last):
  File "/Volumes/Work/ddtech/ddtenv/lib/python3.6/site-packages/django/core/handlers/exception.py", line 34, in inner
    response = get_response(request)
  File "/Volumes/Work/ddtech/ddtenv/lib/python3.6/site-packages/django/core/handlers/base.py", line 126, in _get_response
    response = self.process_exception_by_middleware(e, request)
  File "/Volumes/Work/ddtech/ddtenv/lib/python3.6/site-packages/django/core/handlers/base.py", line 124, in _get_response
    response = wrapped_callback(request, *callback_args, **callback_kwargs)
  File "/Volumes/Work/ddtech/ddtenv/lib/python3.6/site-packages/django/views/decorators/csrf.py", line 54, in wrapped_view
    return view_func(*args, **kwargs)
  File "/Volumes/Work/ddtech/aegis/config/secret.py", line 128, in testEncryptionStr
    _cipherText = AES_ENCRYPT(_plainText)
  File "/Volumes/Work/ddtech/aegis/config/secret.py", line 55, in AES_ENCRYPT
    msg2 = pad(msg, 16, 'pkcs7')
  File "/Volumes/Work/ddtech/aegis/config/secret.py", line 46, in pad
    return data_to_pad + padding
TypeError: must be str, not bytes
2019-01-16 01:58:58,576 [DEBUG] aegis.log: >>> testEncryptionStr: 1234567890ABCDEFGHIJKLMNOPQRSTUVWXYZ%20%EA%B0%80%EB%82%98%EB%8B%A4%EB%9D%BC%EB%A7%88%EB%B0%94%EC%82%AC%EC%95%84%EC%9E%90%EC%B0%A8%EC%B9%B4%ED%83%80%ED%8C%8C%ED%95%98
2019-01-16 01:58:58,576 [DEBUG] aegis.log: 1234567890ABCDEFGHIJKLMNOPQRSTUVWXYZ%20%EA%B0%80%EB%82%98%EB%8B%A4%EB%9D%BC%EB%A7%88%EB%B0%94%EC%82%AC%EC%95%84%EC%9E%90%EC%B0%A8%EC%B9%B4%ED%83%80%ED%8C%8C%ED%95%98
2019-01-16 01:58:58,640 [ERROR] django.request: Internal Server Error: /testEncryptionStr
Traceback (most recent call last):
  File "/Volumes/Work/ddtech/ddtenv/lib/python3.6/site-packages/django/core/handlers/exception.py", line 34, in inner
    response = get_response(request)
  File "/Volumes/Work/ddtech/ddtenv/lib/python3.6/site-packages/django/core/handlers/base.py", line 126, in _get_response
    response = self.process_exception_by_middleware(e, request)
  File "/Volumes/Work/ddtech/ddtenv/lib/python3.6/site-packages/django/core/handlers/base.py", line 124, in _get_response
    response = wrapped_callback(request, *callback_args, **callback_kwargs)
  File "/Volumes/Work/ddtech/ddtenv/lib/python3.6/site-packages/django/views/decorators/csrf.py", line 54, in wrapped_view
    return view_func(*args, **kwargs)
  File "/Volumes/Work/ddtech/aegis/config/secret.py", line 129, in testEncryptionStr
    _cipherText = AES_ENCRYPT(_plainText)
  File "/Volumes/Work/ddtech/aegis/config/secret.py", line 55, in AES_ENCRYPT
    msg2 = pad(msg, 16, 'pkcs7')
  File "/Volumes/Work/ddtech/aegis/config/secret.py", line 46, in pad
    return data_to_pad + padding
TypeError: must be str, not bytes
2019-01-16 01:59:49,695 [DEBUG] aegis.log: >>> testEncryptionStr: 1234567890ABCDEFGHIJKLMNOPQRSTUVWXYZ%20%EA%B0%80%EB%82%98%EB%8B%A4%EB%9D%BC%EB%A7%88%EB%B0%94%EC%82%AC%EC%95%84%EC%9E%90%EC%B0%A8%EC%B9%B4%ED%83%80%ED%8C%8C%ED%95%98
2019-01-16 01:59:49,696 [DEBUG] aegis.log: 1234567890ABCDEFGHIJKLMNOPQRSTUVWXYZ%20%EA%B0%80%EB%82%98%EB%8B%A4%EB%9D%BC%EB%A7%88%EB%B0%94%EC%82%AC%EC%95%84%EC%9E%90%EC%B0%A8%EC%B9%B4%ED%83%80%ED%8C%8C%ED%95%98
2019-01-16 01:59:49,762 [ERROR] django.request: Internal Server Error: /testEncryptionStr
Traceback (most recent call last):
  File "/Volumes/Work/ddtech/ddtenv/lib/python3.6/site-packages/django/core/handlers/exception.py", line 34, in inner
    response = get_response(request)
  File "/Volumes/Work/ddtech/ddtenv/lib/python3.6/site-packages/django/core/handlers/base.py", line 126, in _get_response
    response = self.process_exception_by_middleware(e, request)
  File "/Volumes/Work/ddtech/ddtenv/lib/python3.6/site-packages/django/core/handlers/base.py", line 124, in _get_response
    response = wrapped_callback(request, *callback_args, **callback_kwargs)
  File "/Volumes/Work/ddtech/ddtenv/lib/python3.6/site-packages/django/views/decorators/csrf.py", line 54, in wrapped_view
    return view_func(*args, **kwargs)
  File "/Volumes/Work/ddtech/aegis/config/secret.py", line 130, in testEncryptionStr
    r += '</br>*** cipherText(bytes) = ' + AES_ENCRYPT_HEX(_cipherText)
  File "/Volumes/Work/ddtech/aegis/config/secret.py", line 66, in AES_ENCRYPT_HEX
    cipherText = AES_ENCRYPT(msg)
  File "/Volumes/Work/ddtech/aegis/config/secret.py", line 55, in AES_ENCRYPT
    msg2 = pad(msg.encode(encoding='UTF-8'), 16, 'pkcs7')
AttributeError: 'bytes' object has no attribute 'encode'
2019-01-16 02:02:08,835 [DEBUG] aegis.log: >>> testEncryptionStr: 1234567890ABCDEFGHIJKLMNOPQRSTUVWXYZ%20%EA%B0%80%EB%82%98%EB%8B%A4%EB%9D%BC%EB%A7%88%EB%B0%94%EC%82%AC%EC%95%84%EC%9E%90%EC%B0%A8%EC%B9%B4%ED%83%80%ED%8C%8C%ED%95%98
2019-01-16 02:02:08,835 [DEBUG] aegis.log: 1234567890ABCDEFGHIJKLMNOPQRSTUVWXYZ%20%EA%B0%80%EB%82%98%EB%8B%A4%EB%9D%BC%EB%A7%88%EB%B0%94%EC%82%AC%EC%95%84%EC%9E%90%EC%B0%A8%EC%B9%B4%ED%83%80%ED%8C%8C%ED%95%98
2019-01-16 02:02:08,900 [ERROR] django.request: Internal Server Error: /testEncryptionStr
Traceback (most recent call last):
  File "/Volumes/Work/ddtech/ddtenv/lib/python3.6/site-packages/django/core/handlers/exception.py", line 34, in inner
    response = get_response(request)
  File "/Volumes/Work/ddtech/ddtenv/lib/python3.6/site-packages/django/core/handlers/base.py", line 126, in _get_response
    response = self.process_exception_by_middleware(e, request)
  File "/Volumes/Work/ddtech/ddtenv/lib/python3.6/site-packages/django/core/handlers/base.py", line 124, in _get_response
    response = wrapped_callback(request, *callback_args, **callback_kwargs)
  File "/Volumes/Work/ddtech/ddtenv/lib/python3.6/site-packages/django/views/decorators/csrf.py", line 54, in wrapped_view
    return view_func(*args, **kwargs)
  File "/Volumes/Work/ddtech/aegis/config/secret.py", line 131, in testEncryptionStr
    r += '</br>*** cipherText(bytes) = ' + AES_ENCRYPT_HEX(_cipherText)
  File "/Volumes/Work/ddtech/aegis/config/secret.py", line 66, in AES_ENCRYPT_HEX
    cipherText = AES_ENCRYPT(msg)
  File "/Volumes/Work/ddtech/aegis/config/secret.py", line 55, in AES_ENCRYPT
    msg2 = pad(msg.encode(encoding='UTF-8'), 16, 'pkcs7')
AttributeError: 'bytes' object has no attribute 'encode'
2019-01-16 02:05:47,536 [DEBUG] aegis.log: >>> testEncryptionStr: 1234567890ABCDEFGHIJKLMNOPQRSTUVWXYZ%20%EA%B0%80%EB%82%98%EB%8B%A4%EB%9D%BC%EB%A7%88%EB%B0%94%EC%82%AC%EC%95%84%EC%9E%90%EC%B0%A8%EC%B9%B4%ED%83%80%ED%8C%8C%ED%95%98
2019-01-16 02:05:47,536 [DEBUG] aegis.log: 1234567890ABCDEFGHIJKLMNOPQRSTUVWXYZ%20%EA%B0%80%EB%82%98%EB%8B%A4%EB%9D%BC%EB%A7%88%EB%B0%94%EC%82%AC%EC%95%84%EC%9E%90%EC%B0%A8%EC%B9%B4%ED%83%80%ED%8C%8C%ED%95%98
2019-01-16 02:05:47,600 [ERROR] django.request: Internal Server Error: /testEncryptionStr
Traceback (most recent call last):
  File "/Volumes/Work/ddtech/ddtenv/lib/python3.6/site-packages/django/core/handlers/exception.py", line 34, in inner
    response = get_response(request)
  File "/Volumes/Work/ddtech/ddtenv/lib/python3.6/site-packages/django/core/handlers/base.py", line 126, in _get_response
    response = self.process_exception_by_middleware(e, request)
  File "/Volumes/Work/ddtech/ddtenv/lib/python3.6/site-packages/django/core/handlers/base.py", line 124, in _get_response
    response = wrapped_callback(request, *callback_args, **callback_kwargs)
  File "/Volumes/Work/ddtech/ddtenv/lib/python3.6/site-packages/django/views/decorators/csrf.py", line 54, in wrapped_view
    return view_func(*args, **kwargs)
  File "/Volumes/Work/ddtech/aegis/config/secret.py", line 132, in testEncryptionStr
    r += '</br>*** cipherText(bytes) = ' + AES_ENCRYPT_HEX(_cipherText)
  File "/Volumes/Work/ddtech/aegis/config/secret.py", line 66, in AES_ENCRYPT_HEX
    cipherText = AES_ENCRYPT(msg)
  File "/Volumes/Work/ddtech/aegis/config/secret.py", line 55, in AES_ENCRYPT
    msg2 = pad(msg.encode(encoding='UTF-8'), 16, 'pkcs7')
AttributeError: 'bytes' object has no attribute 'encode'
2019-01-16 02:06:31,568 [DEBUG] aegis.log: >>> testEncryptionStr: 1234567890ABCDEFGHIJKLMNOPQRSTUVWXYZ%20%EA%B0%80%EB%82%98%EB%8B%A4%EB%9D%BC%EB%A7%88%EB%B0%94%EC%82%AC%EC%95%84%EC%9E%90%EC%B0%A8%EC%B9%B4%ED%83%80%ED%8C%8C%ED%95%98
2019-01-16 02:06:31,568 [DEBUG] aegis.log: 1234567890ABCDEFGHIJKLMNOPQRSTUVWXYZ%20%EA%B0%80%EB%82%98%EB%8B%A4%EB%9D%BC%EB%A7%88%EB%B0%94%EC%82%AC%EC%95%84%EC%9E%90%EC%B0%A8%EC%B9%B4%ED%83%80%ED%8C%8C%ED%95%98
2019-01-16 02:06:31,631 [ERROR] django.request: Internal Server Error: /testEncryptionStr
Traceback (most recent call last):
  File "/Volumes/Work/ddtech/ddtenv/lib/python3.6/site-packages/django/core/handlers/exception.py", line 34, in inner
    response = get_response(request)
  File "/Volumes/Work/ddtech/ddtenv/lib/python3.6/site-packages/django/core/handlers/base.py", line 126, in _get_response
    response = self.process_exception_by_middleware(e, request)
  File "/Volumes/Work/ddtech/ddtenv/lib/python3.6/site-packages/django/core/handlers/base.py", line 124, in _get_response
    response = wrapped_callback(request, *callback_args, **callback_kwargs)
  File "/Volumes/Work/ddtech/ddtenv/lib/python3.6/site-packages/django/views/decorators/csrf.py", line 54, in wrapped_view
    return view_func(*args, **kwargs)
  File "/Volumes/Work/ddtech/aegis/config/secret.py", line 132, in testEncryptionStr
    r += '</br>*** cipherText(bytes) = ' + AES_ENCRYPT_HEX(_cipherText)
  File "/Volumes/Work/ddtech/aegis/config/secret.py", line 66, in AES_ENCRYPT_HEX
    cipherText = AES_ENCRYPT(msg)
  File "/Volumes/Work/ddtech/aegis/config/secret.py", line 55, in AES_ENCRYPT
    msg2 = pad(msg.encode(encoding='UTF-8'), 16, 'pkcs7')
AttributeError: 'bytes' object has no attribute 'encode'
2019-01-16 02:07:47,742 [DEBUG] aegis.log: >>> testEncryptionStr: 1234567890ABCDEFGHIJKLMNOPQRSTUVWXYZ%20%EA%B0%80%EB%82%98%EB%8B%A4%EB%9D%BC%EB%A7%88%EB%B0%94%EC%82%AC%EC%95%84%EC%9E%90%EC%B0%A8%EC%B9%B4%ED%83%80%ED%8C%8C%ED%95%98
2019-01-16 02:07:47,743 [DEBUG] aegis.log: 1234567890ABCDEFGHIJKLMNOPQRSTUVWXYZ%20%EA%B0%80%EB%82%98%EB%8B%A4%EB%9D%BC%EB%A7%88%EB%B0%94%EC%82%AC%EC%95%84%EC%9E%90%EC%B0%A8%EC%B9%B4%ED%83%80%ED%8C%8C%ED%95%98
2019-01-16 02:07:47,805 [ERROR] django.request: Internal Server Error: /testEncryptionStr
Traceback (most recent call last):
  File "/Volumes/Work/ddtech/ddtenv/lib/python3.6/site-packages/django/core/handlers/exception.py", line 34, in inner
    response = get_response(request)
  File "/Volumes/Work/ddtech/ddtenv/lib/python3.6/site-packages/django/core/handlers/base.py", line 126, in _get_response
    response = self.process_exception_by_middleware(e, request)
  File "/Volumes/Work/ddtech/ddtenv/lib/python3.6/site-packages/django/core/handlers/base.py", line 124, in _get_response
    response = wrapped_callback(request, *callback_args, **callback_kwargs)
  File "/Volumes/Work/ddtech/ddtenv/lib/python3.6/site-packages/django/views/decorators/csrf.py", line 54, in wrapped_view
    return view_func(*args, **kwargs)
  File "/Volumes/Work/ddtech/aegis/config/secret.py", line 133, in testEncryptionStr
    r += '</br>*** cipherText(bytes) = ' + AES_ENCRYPT_HEX(_cipherText)
  File "/Volumes/Work/ddtech/aegis/config/secret.py", line 71, in AES_ENCRYPT_HEX
    r += '%02X' % ord(ch) + ' '
TypeError: ord() expected string of length 1, but int found
2019-01-16 02:09:10,846 [DEBUG] aegis.log: >>> testEncryptionStr: 1234567890ABCDEFGHIJKLMNOPQRSTUVWXYZ%20%EA%B0%80%EB%82%98%EB%8B%A4%EB%9D%BC%EB%A7%88%EB%B0%94%EC%82%AC%EC%95%84%EC%9E%90%EC%B0%A8%EC%B9%B4%ED%83%80%ED%8C%8C%ED%95%98
2019-01-16 02:09:10,846 [DEBUG] aegis.log: 1234567890ABCDEFGHIJKLMNOPQRSTUVWXYZ%20%EA%B0%80%EB%82%98%EB%8B%A4%EB%9D%BC%EB%A7%88%EB%B0%94%EC%82%AC%EC%95%84%EC%9E%90%EC%B0%A8%EC%B9%B4%ED%83%80%ED%8C%8C%ED%95%98
2019-01-16 02:09:10,909 [ERROR] django.request: Internal Server Error: /testEncryptionStr
Traceback (most recent call last):
  File "/Volumes/Work/ddtech/ddtenv/lib/python3.6/site-packages/django/core/handlers/exception.py", line 34, in inner
    response = get_response(request)
  File "/Volumes/Work/ddtech/ddtenv/lib/python3.6/site-packages/django/core/handlers/base.py", line 126, in _get_response
    response = self.process_exception_by_middleware(e, request)
  File "/Volumes/Work/ddtech/ddtenv/lib/python3.6/site-packages/django/core/handlers/base.py", line 124, in _get_response
    response = wrapped_callback(request, *callback_args, **callback_kwargs)
  File "/Volumes/Work/ddtech/ddtenv/lib/python3.6/site-packages/django/views/decorators/csrf.py", line 54, in wrapped_view
    return view_func(*args, **kwargs)
  File "/Volumes/Work/ddtech/aegis/config/secret.py", line 133, in testEncryptionStr
    r += '</br>*** cipherText(bytes) = ' + AES_ENCRYPT_HEX(_cipherText)
  File "/Volumes/Work/ddtech/aegis/config/secret.py", line 71, in AES_ENCRYPT_HEX
    r += '%02X' % int(ord(ch)) + ' '
TypeError: ord() expected string of length 1, but int found
2019-01-16 02:09:52,089 [DEBUG] aegis.log: >>> testEncryptionStr: 1234567890ABCDEFGHIJKLMNOPQRSTUVWXYZ%20%EA%B0%80%EB%82%98%EB%8B%A4%EB%9D%BC%EB%A7%88%EB%B0%94%EC%82%AC%EC%95%84%EC%9E%90%EC%B0%A8%EC%B9%B4%ED%83%80%ED%8C%8C%ED%95%98
2019-01-16 02:09:52,089 [DEBUG] aegis.log: 1234567890ABCDEFGHIJKLMNOPQRSTUVWXYZ%20%EA%B0%80%EB%82%98%EB%8B%A4%EB%9D%BC%EB%A7%88%EB%B0%94%EC%82%AC%EC%95%84%EC%9E%90%EC%B0%A8%EC%B9%B4%ED%83%80%ED%8C%8C%ED%95%98
2019-01-16 02:09:52,151 [ERROR] django.request: Internal Server Error: /testEncryptionStr
Traceback (most recent call last):
  File "/Volumes/Work/ddtech/ddtenv/lib/python3.6/site-packages/django/core/handlers/exception.py", line 34, in inner
    response = get_response(request)
  File "/Volumes/Work/ddtech/ddtenv/lib/python3.6/site-packages/django/core/handlers/base.py", line 126, in _get_response
    response = self.process_exception_by_middleware(e, request)
  File "/Volumes/Work/ddtech/ddtenv/lib/python3.6/site-packages/django/core/handlers/base.py", line 124, in _get_response
    response = wrapped_callback(request, *callback_args, **callback_kwargs)
  File "/Volumes/Work/ddtech/ddtenv/lib/python3.6/site-packages/django/views/decorators/csrf.py", line 54, in wrapped_view
    return view_func(*args, **kwargs)
  File "/Volumes/Work/ddtech/aegis/config/secret.py", line 138, in testEncryptionStr
    r += '</br>*** base64 cipherText = ' + b64cipherText
TypeError: must be str, not bytes
2019-01-16 02:11:04,145 [DEBUG] aegis.log: >>> testEncryptionStr: 1234567890ABCDEFGHIJKLMNOPQRSTUVWXYZ%20%EA%B0%80%EB%82%98%EB%8B%A4%EB%9D%BC%EB%A7%88%EB%B0%94%EC%82%AC%EC%95%84%EC%9E%90%EC%B0%A8%EC%B9%B4%ED%83%80%ED%8C%8C%ED%95%98
2019-01-16 02:11:04,146 [DEBUG] aegis.log: 1234567890ABCDEFGHIJKLMNOPQRSTUVWXYZ%20%EA%B0%80%EB%82%98%EB%8B%A4%EB%9D%BC%EB%A7%88%EB%B0%94%EC%82%AC%EC%95%84%EC%9E%90%EC%B0%A8%EC%B9%B4%ED%83%80%ED%8C%8C%ED%95%98
2019-01-16 02:11:04,146 [DEBUG] aegis.log: ERROR: AES_DECRYPT
2019-01-16 02:11:04,146 [DEBUG] aegis.log: ......
2019-01-16 02:15:28,622 [DEBUG] aegis.log: >>> testEncryptionStr: 1234567890ABCDEFGHIJKLMNOPQRSTUVWXYZ%20%EA%B0%80%EB%82%98%EB%8B%A4%EB%9D%BC%EB%A7%88%EB%B0%94%EC%82%AC%EC%95%84%EC%9E%90%EC%B0%A8%EC%B9%B4%ED%83%80%ED%8C%8C%ED%95%98
2019-01-16 02:15:28,623 [DEBUG] aegis.log: 1234567890ABCDEFGHIJKLMNOPQRSTUVWXYZ%20%EA%B0%80%EB%82%98%EB%8B%A4%EB%9D%BC%EB%A7%88%EB%B0%94%EC%82%AC%EC%95%84%EC%9E%90%EC%B0%A8%EC%B9%B4%ED%83%80%ED%8C%8C%ED%95%98
2019-01-16 02:15:28,623 [DEBUG] aegis.log: ERROR: AES_DECRYPT
2019-01-16 02:15:28,623 [DEBUG] aegis.log: ......
2019-01-16 02:19:57,712 [DEBUG] aegis.log: >>> testEncryptionStr: 1234567890ABCDEFGHIJKLMNOPQRSTUVWXYZ%20%EA%B0%80%EB%82%98%EB%8B%A4%EB%9D%BC%EB%A7%88%EB%B0%94%EC%82%AC%EC%95%84%EC%9E%90%EC%B0%A8%EC%B9%B4%ED%83%80%ED%8C%8C%ED%95%98
2019-01-16 02:19:57,712 [DEBUG] aegis.log: 1234567890ABCDEFGHIJKLMNOPQRSTUVWXYZ%20%EA%B0%80%EB%82%98%EB%8B%A4%EB%9D%BC%EB%A7%88%EB%B0%94%EC%82%AC%EC%95%84%EC%9E%90%EC%B0%A8%EC%B9%B4%ED%83%80%ED%8C%8C%ED%95%98
2019-01-16 02:19:57,712 [DEBUG] aegis.log: ERROR: AES_DECRYPT
2019-01-16 02:19:57,712 [DEBUG] aegis.log: ......
2019-01-16 02:21:59,673 [DEBUG] aegis.log: >>> testEncryptionStr: 1234567890ABCDEFGHIJKLMNOPQRSTUVWXYZ%20%EA%B0%80%EB%82%98%EB%8B%A4%EB%9D%BC%EB%A7%88%EB%B0%94%EC%82%AC%EC%95%84%EC%9E%90%EC%B0%A8%EC%B9%B4%ED%83%80%ED%8C%8C%ED%95%98
2019-01-16 02:21:59,673 [DEBUG] aegis.log: 1234567890ABCDEFGHIJKLMNOPQRSTUVWXYZ%20%EA%B0%80%EB%82%98%EB%8B%A4%EB%9D%BC%EB%A7%88%EB%B0%94%EC%82%AC%EC%95%84%EC%9E%90%EC%B0%A8%EC%B9%B4%ED%83%80%ED%8C%8C%ED%95%98
2019-01-16 02:21:59,740 [ERROR] django.request: Internal Server Error: /testEncryptionStr
Traceback (most recent call last):
  File "/Volumes/Work/ddtech/ddtenv/lib/python3.6/site-packages/django/core/handlers/exception.py", line 34, in inner
    response = get_response(request)
  File "/Volumes/Work/ddtech/ddtenv/lib/python3.6/site-packages/django/core/handlers/base.py", line 126, in _get_response
    response = self.process_exception_by_middleware(e, request)
  File "/Volumes/Work/ddtech/ddtenv/lib/python3.6/site-packages/django/core/handlers/base.py", line 124, in _get_response
    response = wrapped_callback(request, *callback_args, **callback_kwargs)
  File "/Volumes/Work/ddtech/ddtenv/lib/python3.6/site-packages/django/views/decorators/csrf.py", line 54, in wrapped_view
    return view_func(*args, **kwargs)
  File "/Volumes/Work/ddtech/aegis/config/secret.py", line 176, in testEncryptionStr
    r += '</br>*** replainText = ' + plainText
TypeError: must be str, not bytes
2019-01-16 02:22:55,811 [DEBUG] aegis.log: >>> testEncryptionStr: 1234567890ABCDEFGHIJKLMNOPQRSTUVWXYZ%20%EA%B0%80%EB%82%98%EB%8B%A4%EB%9D%BC%EB%A7%88%EB%B0%94%EC%82%AC%EC%95%84%EC%9E%90%EC%B0%A8%EC%B9%B4%ED%83%80%ED%8C%8C%ED%95%98
2019-01-16 02:22:55,811 [DEBUG] aegis.log: 1234567890ABCDEFGHIJKLMNOPQRSTUVWXYZ%20%EA%B0%80%EB%82%98%EB%8B%A4%EB%9D%BC%EB%A7%88%EB%B0%94%EC%82%AC%EC%95%84%EC%9E%90%EC%B0%A8%EC%B9%B4%ED%83%80%ED%8C%8C%ED%95%98
2019-01-16 02:22:55,811 [DEBUG] aegis.log: b'1234567890ABCDEFGHIJKLMNOPQRSTUVWXYZ%20%EA%B0%80%EB%82%98%EB%8B%A4%EB%9D%BC%EB%A7%88%EB%B0%94%EC%82%AC%EC%95%84%EC%9E%90%EC%B0%A8%EC%B9%B4%ED%83%80%ED%8C%8C%ED%95%98'
2019-01-16 02:24:06,393 [DEBUG] aegis.log: >>> testEncryptionStr: 1234567890ABCDEFGHIJKLMNOPQRSTUVWXYZ%20%EA%B0%80%EB%82%98%EB%8B%A4%EB%9D%BC%EB%A7%88%EB%B0%94%EC%82%AC%EC%95%84%EC%9E%90%EC%B0%A8%EC%B9%B4%ED%83%80%ED%8C%8C%ED%95%98
2019-01-16 02:24:06,393 [DEBUG] aegis.log: 1234567890ABCDEFGHIJKLMNOPQRSTUVWXYZ%20%EA%B0%80%EB%82%98%EB%8B%A4%EB%9D%BC%EB%A7%88%EB%B0%94%EC%82%AC%EC%95%84%EC%9E%90%EC%B0%A8%EC%B9%B4%ED%83%80%ED%8C%8C%ED%95%98
2019-01-16 02:24:06,454 [ERROR] django.request: Internal Server Error: /testEncryptionStr
Traceback (most recent call last):
  File "/Volumes/Work/ddtech/ddtenv/lib/python3.6/site-packages/django/core/handlers/exception.py", line 34, in inner
    response = get_response(request)
  File "/Volumes/Work/ddtech/ddtenv/lib/python3.6/site-packages/django/core/handlers/base.py", line 126, in _get_response
    response = self.process_exception_by_middleware(e, request)
  File "/Volumes/Work/ddtech/ddtenv/lib/python3.6/site-packages/django/core/handlers/base.py", line 124, in _get_response
    response = wrapped_callback(request, *callback_args, **callback_kwargs)
  File "/Volumes/Work/ddtech/ddtenv/lib/python3.6/site-packages/django/views/decorators/csrf.py", line 54, in wrapped_view
    return view_func(*args, **kwargs)
  File "/Volumes/Work/ddtech/aegis/config/secret.py", line 176, in testEncryptionStr
    r += '</br>*** replainText = ' + plainText.encode(encoding='UTF-8')
TypeError: must be str, not bytes
2019-01-16 02:25:32,506 [WARNING] django.request: Bad Request: /dr/testDecryptionStr
2019-01-16 02:25:32,621 [WARNING] django.request: Bad Request: /favicon.ico
2019-01-16 02:25:45,303 [WARNING] django.request: Bad Request: /dr/testDecryptionStr
2019-01-16 02:26:07,828 [DEBUG] aegis.log: >>> testDecryptionStr: bPRlRWGlo2jEJ0o1UuzqFG_-YCFOJLZn9LFk_213X0rbrALoPyF3x1YhRobhUdJCvk13FUA8Xrs4F0aajD3r-4ak9GYxYD97Plo1CAtxtS77Z7rsYFqTak_JKo3pSCTm
2019-01-16 02:26:07,828 [DEBUG] aegis.log: ERROR: base64decode
2019-01-16 02:26:07,855 [ERROR] django.request: Internal Server Error: /dr/testDecryptionStr
Traceback (most recent call last):
  File "/Volumes/Work/ddtech/ddtenv/lib/python3.6/site-packages/django/core/handlers/exception.py", line 34, in inner
    response = get_response(request)
  File "/Volumes/Work/ddtech/ddtenv/lib/python3.6/site-packages/django/core/handlers/base.py", line 126, in _get_response
    response = self.process_exception_by_middleware(e, request)
  File "/Volumes/Work/ddtech/ddtenv/lib/python3.6/site-packages/django/core/handlers/base.py", line 124, in _get_response
    response = wrapped_callback(request, *callback_args, **callback_kwargs)
  File "/Volumes/Work/ddtech/ddtenv/lib/python3.6/site-packages/django/views/decorators/csrf.py", line 54, in wrapped_view
    return view_func(*args, **kwargs)
  File "/Volumes/Work/ddtech/aegis/config/secret.py", line 199, in testDecryptionStr
    r += '</br>*** cipherText = ' + _cipherText.hex()
AttributeError: 'str' object has no attribute 'hex'
2019-01-16 02:26:07,949 [WARNING] django.request: Not Found: /favicon.ico
2019-01-16 02:26:56,764 [DEBUG] aegis.log: >>> testDecryptionStr: bPRlRWGlo2jEJ0o1UuzqFG_-YCFOJLZn9LFk_213X0rbrALoPyF3x1YhRobhUdJCvk13FUA8Xrs4F0aajD3r-4ak9GYxYD97Plo1CAtxtS77Z7rsYFqTak_JKo3pSCTm
2019-01-16 02:26:56,765 [DEBUG] aegis.log: ERROR: base64decode
2019-01-16 02:26:56,825 [ERROR] django.request: Internal Server Error: /dr/testDecryptionStr
Traceback (most recent call last):
  File "/Volumes/Work/ddtech/ddtenv/lib/python3.6/site-packages/django/core/handlers/exception.py", line 34, in inner
    response = get_response(request)
  File "/Volumes/Work/ddtech/ddtenv/lib/python3.6/site-packages/django/core/handlers/base.py", line 126, in _get_response
    response = self.process_exception_by_middleware(e, request)
  File "/Volumes/Work/ddtech/ddtenv/lib/python3.6/site-packages/django/core/handlers/base.py", line 124, in _get_response
    response = wrapped_callback(request, *callback_args, **callback_kwargs)
  File "/Volumes/Work/ddtech/ddtenv/lib/python3.6/site-packages/django/views/decorators/csrf.py", line 54, in wrapped_view
    return view_func(*args, **kwargs)
  File "/Volumes/Work/ddtech/aegis/config/secret.py", line 199, in testDecryptionStr
    r += '</br>*** cipherText = ' + _cipherText.hex()
AttributeError: 'str' object has no attribute 'hex'
2019-01-16 02:27:49,515 [DEBUG] aegis.log: >>> testDecryptionStr: bPRlRWGlo2jEJ0o1UuzqFG_-YCFOJLZn9LFk_213X0rbrALoPyF3x1YhRobhUdJCvk13FUA8Xrs4F0aajD3r-4ak9GYxYD97Plo1CAtxtS77Z7rsYFqTak_JKo3pSCTm
2019-01-16 02:27:49,515 [DEBUG] aegis.log: ERROR: base64decode
2019-01-16 02:27:49,516 [DEBUG] aegis.log: ERROR: AES_DECRYPT
2019-01-16 02:27:49,577 [ERROR] django.request: Internal Server Error: /dr/testDecryptionStr
Traceback (most recent call last):
  File "/Volumes/Work/ddtech/ddtenv/lib/python3.6/site-packages/django/core/handlers/exception.py", line 34, in inner
    response = get_response(request)
  File "/Volumes/Work/ddtech/ddtenv/lib/python3.6/site-packages/django/core/handlers/base.py", line 126, in _get_response
    response = self.process_exception_by_middleware(e, request)
  File "/Volumes/Work/ddtech/ddtenv/lib/python3.6/site-packages/django/core/handlers/base.py", line 124, in _get_response
    response = wrapped_callback(request, *callback_args, **callback_kwargs)
  File "/Volumes/Work/ddtech/ddtenv/lib/python3.6/site-packages/django/views/decorators/csrf.py", line 54, in wrapped_view
    return view_func(*args, **kwargs)
  File "/Volumes/Work/ddtech/aegis/config/secret.py", line 202, in testDecryptionStr
    logSend(plainText.decode('utf-8'))
AttributeError: 'str' object has no attribute 'decode'
2019-01-16 02:28:21,252 [DEBUG] aegis.log: >>> testDecryptionStr: bPRlRWGlo2jEJ0o1UuzqFG_-YCFOJLZn9LFk_213X0rbrALoPyF3x1YhRobhUdJCvk13FUA8Xrs4F0aajD3r-4ak9GYxYD97Plo1CAtxtS77Z7rsYFqTak_JKo3pSCTm
2019-01-16 02:28:21,253 [DEBUG] aegis.log: ERROR: base64decode
2019-01-16 02:28:21,253 [DEBUG] aegis.log: ERROR: AES_DECRYPT
2019-01-16 02:29:55,776 [DEBUG] aegis.log: >>> testDecryptionStr: bPRlRWGlo2jEJ0o1UuzqFG_-YCFOJLZn9LFk_213X0rbrALoPyF3x1YhRobhUdJCvk13FUA8Xrs4F0aajD3r-4ak9GYxYD97Plo1CAtxtS77Z7rsYFqTak_JKo3pSCTm
2019-01-16 02:29:55,776 [DEBUG] aegis.log: ERROR: base64decode
2019-01-16 02:29:55,776 [DEBUG] aegis.log: ERROR: AES_DECRYPT
2019-01-16 02:30:27,668 [DEBUG] aegis.log: >>> testDecryptionStr: bPRlRWGlo2jEJ0o1UuzqFG_-YCFOJLZn9LFk_213X0rbrALoPyF3x1YhRobhUdJCvk13FUA8Xrs4F0aajD3r-4ak9GYxYD97Plo1CAtxtS77Z7rsYFqTak_JKo3pSCTm
2019-01-16 02:30:27,668 [DEBUG] aegis.log: ERROR: base64decode
2019-01-16 02:30:27,668 [DEBUG] aegis.log: ERROR: AES_DECRYPT
2019-01-16 02:31:12,668 [DEBUG] aegis.log: >>> testDecryptionStr: bPRlRWGlo2jEJ0o1UuzqFG_-YCFOJLZn9LFk_213X0rbrALoPyF3x1YhRobhUdJCvk13FUA8Xrs4F0aajD3r-4ak9GYxYD97Plo1CAtxtS77Z7rsYFqTak_JKo3pSCTm
2019-01-16 02:31:12,669 [DEBUG] aegis.log: ERROR: base64decode
2019-01-16 02:31:12,669 [DEBUG] aegis.log: ERROR: AES_DECRYPT
2019-01-16 02:35:09,627 [DEBUG] aegis.log: >>> testDecryptionStr: bPRlRWGlo2jEJ0o1UuzqFG_-YCFOJLZn9LFk_213X0rbrALoPyF3x1YhRobhUdJCvk13FUA8Xrs4F0aajD3r-4ak9GYxYD97Plo1CAtxtS77Z7rsYFqTak_JKo3pSCTm
2019-01-16 02:35:09,628 [DEBUG] aegis.log: ERROR: base64decode
2019-01-16 02:35:09,628 [DEBUG] aegis.log: ERROR: AES_DECRYPT
2019-01-16 02:36:31,387 [DEBUG] aegis.log: >>> testDecryptionStr: bPRlRWGlo2jEJ0o1UuzqFG_-YCFOJLZn9LFk_213X0rbrALoPyF3x1YhRobhUdJCvk13FUA8Xrs4F0aajD3r-4ak9GYxYD97Plo1CAtxtS77Z7rsYFqTak_JKo3pSCTm
2019-01-16 02:36:31,387 [DEBUG] aegis.log: ERROR: base64decode
2019-01-16 02:36:31,387 [DEBUG] aegis.log: ERROR: AES_DECRYPT
2019-01-16 02:37:05,784 [DEBUG] aegis.log: >>> testDecryptionStr: bPRlRWGlo2jEJ0o1UuzqFG_-YCFOJLZn9LFk_213X0rbrALoPyF3x1YhRobhUdJCvk13FUA8Xrs4F0aajD3r-4ak9GYxYD97Plo1CAtxtS77Z7rsYFqTak_JKo3pSCTm
2019-01-16 02:37:05,785 [DEBUG] aegis.log: ERROR: base64decode
2019-01-16 02:37:05,785 [DEBUG] aegis.log: ERROR: AES_DECRYPT
2019-01-16 02:38:00,639 [DEBUG] aegis.log: >>> testDecryptionStr: bPRlRWGlo2jEJ0o1UuzqFG_-YCFOJLZn9LFk_213X0rbrALoPyF3x1YhRobhUdJCvk13FUA8Xrs4F0aajD3r-4ak9GYxYD97Plo1CAtxtS77Z7rsYFqTak_JKo3pSCTm
2019-01-16 02:38:00,640 [DEBUG] aegis.log: ERROR: base64decode
2019-01-16 02:38:00,640 [DEBUG] aegis.log: ERROR: AES_DECRYPT
2019-01-16 02:38:54,651 [DEBUG] aegis.log: >>> testDecryptionStr: bPRlRWGlo2jEJ0o1UuzqFG_-YCFOJLZn9LFk_213X0rbrALoPyF3x1YhRobhUdJCvk13FUA8Xrs4F0aajD3r-4ak9GYxYD97Plo1CAtxtS77Z7rsYFqTak_JKo3pSCTm
2019-01-16 02:38:54,651 [DEBUG] aegis.log: ERROR: base64decode
2019-01-16 02:38:54,651 [DEBUG] aegis.log: ERROR: AES_DECRYPT
2019-01-16 02:39:18,332 [DEBUG] aegis.log: >>> testDecryptionStr: bPRlRWGlo2jEJ0o1UuzqFG_-YCFOJLZn9LFk_213X0rbrALoPyF3x1YhRobhUdJCvk13FUA8Xrs4F0aajD3r-4ak9GYxYD97Plo1CAtxtS77Z7rsYFqTak_JKo3pSCTm
2019-01-16 02:39:18,332 [DEBUG] aegis.log: ERROR: base64decode
2019-01-16 02:39:18,332 [DEBUG] aegis.log: ERROR: AES_DECRYPT
2019-01-16 02:39:34,960 [DEBUG] aegis.log: >>> testDecryptionStr: bPRlRWGlo2jEJ0o1UuzqFG_-YCFOJLZn9LFk_213X0rbrALoPyF3x1YhRobhUdJCvk13FUA8Xrs4F0aajD3r-4ak9GYxYD97Plo1CAtxtS77Z7rsYFqTak_JKo3pSCTm
2019-01-16 02:39:34,960 [DEBUG] aegis.log: ERROR: AES_DECRYPT
2019-01-16 02:41:05,061 [DEBUG] aegis.log: >>> testDecryptionStr: bPRlRWGlo2jEJ0o1UuzqFG_-YCFOJLZn9LFk_213X0rbrALoPyF3x1YhRobhUdJCvk13FUA8Xrs4F0aajD3r-4ak9GYxYD97Plo1CAtxtS77Z7rsYFqTak_JKo3pSCTm
2019-01-16 02:41:05,122 [ERROR] django.request: Internal Server Error: /dr/testDecryptionStr
Traceback (most recent call last):
  File "/Volumes/Work/ddtech/ddtenv/lib/python3.6/site-packages/django/core/handlers/exception.py", line 34, in inner
    response = get_response(request)
  File "/Volumes/Work/ddtech/ddtenv/lib/python3.6/site-packages/django/core/handlers/base.py", line 126, in _get_response
    response = self.process_exception_by_middleware(e, request)
  File "/Volumes/Work/ddtech/ddtenv/lib/python3.6/site-packages/django/core/handlers/base.py", line 124, in _get_response
    response = wrapped_callback(request, *callback_args, **callback_kwargs)
  File "/Volumes/Work/ddtech/ddtenv/lib/python3.6/site-packages/django/views/decorators/csrf.py", line 54, in wrapped_view
    return view_func(*args, **kwargs)
  File "/Volumes/Work/ddtech/aegis/config/secret.py", line 206, in testDecryptionStr
    r += '</br>*** cipherText = ' + _cipherText
TypeError: must be str, not bytes
2019-01-16 03:03:47,755 [DEBUG] aegis.log: >>> testDecryptionStr: bPRlRWGlo2jEJ0o1UuzqFG_-YCFOJLZn9LFk_213X0rbrALoPyF3x1YhRobhUdJCvk13FUA8Xrs4F0aajD3r-4ak9GYxYD97Plo1CAtxtS77Z7rsYFqTak_JKo3pSCTm
2019-01-16 03:03:47,755 [DEBUG] aegis.log: ERROR: AES_DECRYPT
2019-01-16 03:05:29,286 [DEBUG] aegis.log: >>> testDecryptionStr: bPRlRWGlo2jEJ0o1UuzqFG_-YCFOJLZn9LFk_213X0rbrALoPyF3x1YhRobhUdJCvk13FUA8Xrs4F0aajD3r-4ak9GYxYD97Plo1CAtxtS77Z7rsYFqTak_JKo3pSCTm
2019-01-16 03:05:29,287 [DEBUG] aegis.log: ERROR: AES_DECRYPT
2019-01-16 03:08:06,932 [DEBUG] aegis.log: >>> testDecryptionStr: bPRlRWGlo2jEJ0o1UuzqFG_-YCFOJLZn9LFk_213X0rbrALoPyF3x1YhRobhUdJCvk13FUA8Xrs4F0aajD3r-4ak9GYxYD97Plo1CAtxtS77Z7rsYFqTak_JKo3pSCTm
2019-01-16 03:08:06,933 [DEBUG] aegis.log: ERROR: AES_DECRYPT
2019-01-16 03:08:56,826 [DEBUG] aegis.log: >>> testDecryptionStr: bPRlRWGlo2jEJ0o1UuzqFG_-YCFOJLZn9LFk_213X0rbrALoPyF3x1YhRobhUdJCvk13FUA8Xrs4F0aajD3r-4ak9GYxYD97Plo1CAtxtS77Z7rsYFqTak_JKo3pSCTm
2019-01-16 03:08:56,886 [ERROR] django.request: Internal Server Error: /dr/testDecryptionStr
Traceback (most recent call last):
  File "/Volumes/Work/ddtech/ddtenv/lib/python3.6/site-packages/django/core/handlers/exception.py", line 34, in inner
    response = get_response(request)
  File "/Volumes/Work/ddtech/ddtenv/lib/python3.6/site-packages/django/core/handlers/base.py", line 126, in _get_response
    response = self.process_exception_by_middleware(e, request)
  File "/Volumes/Work/ddtech/ddtenv/lib/python3.6/site-packages/django/core/handlers/base.py", line 124, in _get_response
    response = wrapped_callback(request, *callback_args, **callback_kwargs)
  File "/Volumes/Work/ddtech/ddtenv/lib/python3.6/site-packages/django/views/decorators/csrf.py", line 54, in wrapped_view
    return view_func(*args, **kwargs)
  File "/Volumes/Work/ddtech/aegis/config/secret.py", line 210, in testDecryptionStr
    r += '</br>*** plainText = ' + plainText
TypeError: must be str, not bytes
2019-01-16 03:09:46,508 [DEBUG] aegis.log: >>> testDecryptionStr: bPRlRWGlo2jEJ0o1UuzqFG_-YCFOJLZn9LFk_213X0rbrALoPyF3x1YhRobhUdJCvk13FUA8Xrs4F0aajD3r-4ak9GYxYD97Plo1CAtxtS77Z7rsYFqTak_JKo3pSCTm
2019-01-16 03:10:14,440 [DEBUG] aegis.log: >>> testDecryptionStr: bPRlRWGlo2jEJ0o1UuzqFG_-YCFOJLZn9LFk_213X0rbrALoPyF3x1YhRobhUdJCvk13FUA8Xrs4F0aajD3r-4ak9GYxYD97Plo1CAtxtS77Z7rsYFqTak_JKo3pSCTm
2019-01-16 03:10:14,502 [ERROR] django.request: Internal Server Error: /dr/testDecryptionStr
Traceback (most recent call last):
  File "/Volumes/Work/ddtech/ddtenv/lib/python3.6/site-packages/django/core/handlers/exception.py", line 34, in inner
    response = get_response(request)
  File "/Volumes/Work/ddtech/ddtenv/lib/python3.6/site-packages/django/core/handlers/base.py", line 126, in _get_response
    response = self.process_exception_by_middleware(e, request)
  File "/Volumes/Work/ddtech/ddtenv/lib/python3.6/site-packages/django/core/handlers/base.py", line 124, in _get_response
    response = wrapped_callback(request, *callback_args, **callback_kwargs)
  File "/Volumes/Work/ddtech/ddtenv/lib/python3.6/site-packages/django/views/decorators/csrf.py", line 54, in wrapped_view
    return view_func(*args, **kwargs)
  File "/Volumes/Work/ddtech/aegis/config/secret.py", line 211, in testDecryptionStr
    print(plainText.encode(encoding='UTF-8'))
AttributeError: 'bytes' object has no attribute 'encode'
2019-01-16 03:10:31,450 [DEBUG] aegis.log: >>> testDecryptionStr: bPRlRWGlo2jEJ0o1UuzqFG_-YCFOJLZn9LFk_213X0rbrALoPyF3x1YhRobhUdJCvk13FUA8Xrs4F0aajD3r-4ak9GYxYD97Plo1CAtxtS77Z7rsYFqTak_JKo3pSCTm
2019-01-16 03:11:23,403 [DEBUG] aegis.log: >>> testDecryptionStr: bPRlRWGlo2jEJ0o1UuzqFG_-YCFOJLZn9LFk_213X0rbrALoPyF3x1YhRobhUdJCvk13FUA8Xrs4F0aajD3r-4ak9GYxYD97Plo1CAtxtS77Z7rsYFqTak_JKo3pSCTm
2019-01-16 03:11:55,655 [DEBUG] aegis.log: >>> testEncryptionStr: 1234567890ABCDEFGHIJKLMNOPQRSTUVWXYZ%20%EA%B0%80%EB%82%98%EB%8B%A4%EB%9D%BC%EB%A7%88%EB%B0%94%EC%82%AC%EC%95%84%EC%9E%90%EC%B0%A8%EC%B9%B4%ED%83%80%ED%8C%8C%ED%95%98
2019-01-16 03:11:55,656 [DEBUG] aegis.log: 1234567890ABCDEFGHIJKLMNOPQRSTUVWXYZ%20%EA%B0%80%EB%82%98%EB%8B%A4%EB%9D%BC%EB%A7%88%EB%B0%94%EC%82%AC%EC%95%84%EC%9E%90%EC%B0%A8%EC%B9%B4%ED%83%80%ED%8C%8C%ED%95%98
2019-01-16 03:11:55,656 [DEBUG] aegis.log: ERROR: base64decode
2019-01-16 03:11:55,716 [ERROR] django.request: Internal Server Error: /testEncryptionStr
Traceback (most recent call last):
  File "/Volumes/Work/ddtech/ddtenv/lib/python3.6/site-packages/django/core/handlers/exception.py", line 34, in inner
    response = get_response(request)
  File "/Volumes/Work/ddtech/ddtenv/lib/python3.6/site-packages/django/core/handlers/base.py", line 126, in _get_response
    response = self.process_exception_by_middleware(e, request)
  File "/Volumes/Work/ddtech/ddtenv/lib/python3.6/site-packages/django/core/handlers/base.py", line 124, in _get_response
    response = wrapped_callback(request, *callback_args, **callback_kwargs)
  File "/Volumes/Work/ddtech/ddtenv/lib/python3.6/site-packages/django/views/decorators/csrf.py", line 54, in wrapped_view
    return view_func(*args, **kwargs)
  File "/Volumes/Work/ddtech/aegis/config/secret.py", line 181, in testEncryptionStr
    r += '</br>*** cipherText(bytes) = ' + cipherText.hex()
AttributeError: 'str' object has no attribute 'hex'
2019-01-16 03:16:43,083 [DEBUG] aegis.log: >>> testEncryptionStr: 1234567890ABCDEFGHIJKLMNOPQRSTUVWXYZ%20%EA%B0%80%EB%82%98%EB%8B%A4%EB%9D%BC%EB%A7%88%EB%B0%94%EC%82%AC%EC%95%84%EC%9E%90%EC%B0%A8%EC%B9%B4%ED%83%80%ED%8C%8C%ED%95%98
2019-01-16 03:16:43,083 [DEBUG] aegis.log: 1234567890ABCDEFGHIJKLMNOPQRSTUVWXYZ%20%EA%B0%80%EB%82%98%EB%8B%A4%EB%9D%BC%EB%A7%88%EB%B0%94%EC%82%AC%EC%95%84%EC%9E%90%EC%B0%A8%EC%B9%B4%ED%83%80%ED%8C%8C%ED%95%98
2019-01-16 03:16:43,144 [ERROR] django.request: Internal Server Error: /testEncryptionStr
Traceback (most recent call last):
  File "/Volumes/Work/ddtech/ddtenv/lib/python3.6/site-packages/django/core/handlers/exception.py", line 34, in inner
    response = get_response(request)
  File "/Volumes/Work/ddtech/ddtenv/lib/python3.6/site-packages/django/core/handlers/base.py", line 126, in _get_response
    response = self.process_exception_by_middleware(e, request)
  File "/Volumes/Work/ddtech/ddtenv/lib/python3.6/site-packages/django/core/handlers/base.py", line 124, in _get_response
    response = wrapped_callback(request, *callback_args, **callback_kwargs)
  File "/Volumes/Work/ddtech/ddtenv/lib/python3.6/site-packages/django/views/decorators/csrf.py", line 54, in wrapped_view
    return view_func(*args, **kwargs)
  File "/Volumes/Work/ddtech/aegis/config/secret.py", line 177, in testEncryptionStr
    r += '</br>*** base64 cipherText = ' + b64cipherText
TypeError: must be str, not bytes
2019-01-16 03:17:55,770 [DEBUG] aegis.log: >>> testEncryptionStr: 1234567890ABCDEFGHIJKLMNOPQRSTUVWXYZ%20%EA%B0%80%EB%82%98%EB%8B%A4%EB%9D%BC%EB%A7%88%EB%B0%94%EC%82%AC%EC%95%84%EC%9E%90%EC%B0%A8%EC%B9%B4%ED%83%80%ED%8C%8C%ED%95%98
2019-01-16 03:17:55,770 [DEBUG] aegis.log: 1234567890ABCDEFGHIJKLMNOPQRSTUVWXYZ%20%EA%B0%80%EB%82%98%EB%8B%A4%EB%9D%BC%EB%A7%88%EB%B0%94%EC%82%AC%EC%95%84%EC%9E%90%EC%B0%A8%EC%B9%B4%ED%83%80%ED%8C%8C%ED%95%98
2019-01-16 03:17:55,770 [DEBUG] aegis.log: ERROR: base64decode
2019-01-16 03:17:55,771 [DEBUG] aegis.log: ERROR: AES_DECRYPT
2019-01-16 03:17:55,832 [ERROR] django.request: Internal Server Error: /testEncryptionStr
Traceback (most recent call last):
  File "/Volumes/Work/ddtech/ddtenv/lib/python3.6/site-packages/django/core/handlers/exception.py", line 34, in inner
    response = get_response(request)
  File "/Volumes/Work/ddtech/ddtenv/lib/python3.6/site-packages/django/core/handlers/base.py", line 126, in _get_response
    response = self.process_exception_by_middleware(e, request)
  File "/Volumes/Work/ddtech/ddtenv/lib/python3.6/site-packages/django/core/handlers/base.py", line 124, in _get_response
    response = wrapped_callback(request, *callback_args, **callback_kwargs)
  File "/Volumes/Work/ddtech/ddtenv/lib/python3.6/site-packages/django/views/decorators/csrf.py", line 54, in wrapped_view
    return view_func(*args, **kwargs)
  File "/Volumes/Work/ddtech/aegis/config/secret.py", line 185, in testEncryptionStr
    r += '</br>*** replainText = ' + plainText.encode(encoding='UTF-8')
TypeError: must be str, not bytes
2019-01-16 03:18:29,925 [DEBUG] aegis.log: >>> testEncryptionStr: 1234567890ABCDEFGHIJKLMNOPQRSTUVWXYZ%20%EA%B0%80%EB%82%98%EB%8B%A4%EB%9D%BC%EB%A7%88%EB%B0%94%EC%82%AC%EC%95%84%EC%9E%90%EC%B0%A8%EC%B9%B4%ED%83%80%ED%8C%8C%ED%95%98
2019-01-16 03:18:29,926 [DEBUG] aegis.log: 1234567890ABCDEFGHIJKLMNOPQRSTUVWXYZ%20%EA%B0%80%EB%82%98%EB%8B%A4%EB%9D%BC%EB%A7%88%EB%B0%94%EC%82%AC%EC%95%84%EC%9E%90%EC%B0%A8%EC%B9%B4%ED%83%80%ED%8C%8C%ED%95%98
2019-01-16 03:18:29,926 [DEBUG] aegis.log: ERROR: base64decode
2019-01-16 03:18:29,926 [DEBUG] aegis.log: ERROR: AES_DECRYPT
2019-01-16 03:18:29,987 [ERROR] django.request: Internal Server Error: /testEncryptionStr
Traceback (most recent call last):
  File "/Volumes/Work/ddtech/ddtenv/lib/python3.6/site-packages/django/core/handlers/exception.py", line 34, in inner
    response = get_response(request)
  File "/Volumes/Work/ddtech/ddtenv/lib/python3.6/site-packages/django/core/handlers/base.py", line 126, in _get_response
    response = self.process_exception_by_middleware(e, request)
  File "/Volumes/Work/ddtech/ddtenv/lib/python3.6/site-packages/django/core/handlers/base.py", line 124, in _get_response
    response = wrapped_callback(request, *callback_args, **callback_kwargs)
  File "/Volumes/Work/ddtech/ddtenv/lib/python3.6/site-packages/django/views/decorators/csrf.py", line 54, in wrapped_view
    return view_func(*args, **kwargs)
  File "/Volumes/Work/ddtech/aegis/config/secret.py", line 185, in testEncryptionStr
    r += '</br>*** replainText = ' + str(plainText).encode(encoding='UTF-8')
TypeError: must be str, not bytes
2019-01-16 03:19:13,710 [DEBUG] aegis.log: >>> testEncryptionStr: 1234567890ABCDEFGHIJKLMNOPQRSTUVWXYZ%20%EA%B0%80%EB%82%98%EB%8B%A4%EB%9D%BC%EB%A7%88%EB%B0%94%EC%82%AC%EC%95%84%EC%9E%90%EC%B0%A8%EC%B9%B4%ED%83%80%ED%8C%8C%ED%95%98
2019-01-16 03:19:13,711 [DEBUG] aegis.log: 1234567890ABCDEFGHIJKLMNOPQRSTUVWXYZ%20%EA%B0%80%EB%82%98%EB%8B%A4%EB%9D%BC%EB%A7%88%EB%B0%94%EC%82%AC%EC%95%84%EC%9E%90%EC%B0%A8%EC%B9%B4%ED%83%80%ED%8C%8C%ED%95%98
2019-01-16 03:19:13,711 [DEBUG] aegis.log: ERROR: base64decode
2019-01-16 03:19:13,711 [DEBUG] aegis.log: ERROR: AES_DECRYPT
2019-01-16 03:19:13,771 [ERROR] django.request: Internal Server Error: /testEncryptionStr
Traceback (most recent call last):
  File "/Volumes/Work/ddtech/ddtenv/lib/python3.6/site-packages/django/core/handlers/exception.py", line 34, in inner
    response = get_response(request)
  File "/Volumes/Work/ddtech/ddtenv/lib/python3.6/site-packages/django/core/handlers/base.py", line 126, in _get_response
    response = self.process_exception_by_middleware(e, request)
  File "/Volumes/Work/ddtech/ddtenv/lib/python3.6/site-packages/django/core/handlers/base.py", line 124, in _get_response
    response = wrapped_callback(request, *callback_args, **callback_kwargs)
  File "/Volumes/Work/ddtech/ddtenv/lib/python3.6/site-packages/django/views/decorators/csrf.py", line 54, in wrapped_view
    return view_func(*args, **kwargs)
  File "/Volumes/Work/ddtech/aegis/config/secret.py", line 185, in testEncryptionStr
    r += '</br>*** replainText = ' + plainText.hex()
AttributeError: 'str' object has no attribute 'hex'
2019-01-16 03:19:32,823 [DEBUG] aegis.log: >>> testEncryptionStr: 1234567890ABCDEFGHIJKLMNOPQRSTUVWXYZ%20%EA%B0%80%EB%82%98%EB%8B%A4%EB%9D%BC%EB%A7%88%EB%B0%94%EC%82%AC%EC%95%84%EC%9E%90%EC%B0%A8%EC%B9%B4%ED%83%80%ED%8C%8C%ED%95%98
2019-01-16 03:19:32,824 [DEBUG] aegis.log: 1234567890ABCDEFGHIJKLMNOPQRSTUVWXYZ%20%EA%B0%80%EB%82%98%EB%8B%A4%EB%9D%BC%EB%A7%88%EB%B0%94%EC%82%AC%EC%95%84%EC%9E%90%EC%B0%A8%EC%B9%B4%ED%83%80%ED%8C%8C%ED%95%98
2019-01-16 03:19:32,824 [DEBUG] aegis.log: ERROR: base64decode
2019-01-16 03:19:32,824 [DEBUG] aegis.log: ERROR: AES_DECRYPT
2019-01-16 03:19:32,824 [DEBUG] aegis.log: ......
2019-01-16 03:22:28,437 [DEBUG] aegis.log: >>> testEncryptionStr: 1234567890ABCDEFGHIJKLMNOPQRSTUVWXYZ%20%EA%B0%80%EB%82%98%EB%8B%A4%EB%9D%BC%EB%A7%88%EB%B0%94%EC%82%AC%EC%95%84%EC%9E%90%EC%B0%A8%EC%B9%B4%ED%83%80%ED%8C%8C%ED%95%98
2019-01-16 03:22:28,437 [DEBUG] aegis.log: 1234567890ABCDEFGHIJKLMNOPQRSTUVWXYZ%20%EA%B0%80%EB%82%98%EB%8B%A4%EB%9D%BC%EB%A7%88%EB%B0%94%EC%82%AC%EC%95%84%EC%9E%90%EC%B0%A8%EC%B9%B4%ED%83%80%ED%8C%8C%ED%95%98
2019-01-16 03:22:28,438 [DEBUG] aegis.log: ERROR: base64decode
2019-01-16 03:22:28,438 [DEBUG] aegis.log: ERROR: AES_DECRYPT
2019-01-16 03:22:28,438 [DEBUG] aegis.log: ......
2019-01-16 03:30:07,090 [DEBUG] aegis.log: >>> testEncryptionStr: 1234567890ABCDEFGHIJKLMNOPQRSTUVWXYZ%20%EA%B0%80%EB%82%98%EB%8B%A4%EB%9D%BC%EB%A7%88%EB%B0%94%EC%82%AC%EC%95%84%EC%9E%90%EC%B0%A8%EC%B9%B4%ED%83%80%ED%8C%8C%ED%95%98
2019-01-16 03:30:07,090 [DEBUG] aegis.log: 1234567890ABCDEFGHIJKLMNOPQRSTUVWXYZ%20%EA%B0%80%EB%82%98%EB%8B%A4%EB%9D%BC%EB%A7%88%EB%B0%94%EC%82%AC%EC%95%84%EC%9E%90%EC%B0%A8%EC%B9%B4%ED%83%80%ED%8C%8C%ED%95%98
2019-01-16 03:30:07,151 [ERROR] django.request: Internal Server Error: /testEncryptionStr
Traceback (most recent call last):
  File "/Volumes/Work/ddtech/ddtenv/lib/python3.6/site-packages/django/core/handlers/exception.py", line 34, in inner
    response = get_response(request)
  File "/Volumes/Work/ddtech/ddtenv/lib/python3.6/site-packages/django/core/handlers/base.py", line 126, in _get_response
    response = self.process_exception_by_middleware(e, request)
  File "/Volumes/Work/ddtech/ddtenv/lib/python3.6/site-packages/django/core/handlers/base.py", line 124, in _get_response
    response = wrapped_callback(request, *callback_args, **callback_kwargs)
  File "/Volumes/Work/ddtech/ddtenv/lib/python3.6/site-packages/django/views/decorators/csrf.py", line 54, in wrapped_view
    return view_func(*args, **kwargs)
  File "/Volumes/Work/ddtech/aegis/config/secret.py", line 185, in testEncryptionStr
    r += '</br>*** replainText = ' + plainText
TypeError: must be str, not bytes
2019-01-16 03:30:54,868 [DEBUG] aegis.log: >>> testEncryptionStr: 1234567890ABCDEFGHIJKLMNOPQRSTUVWXYZ%20%EA%B0%80%EB%82%98%EB%8B%A4%EB%9D%BC%EB%A7%88%EB%B0%94%EC%82%AC%EC%95%84%EC%9E%90%EC%B0%A8%EC%B9%B4%ED%83%80%ED%8C%8C%ED%95%98
2019-01-16 03:30:54,868 [DEBUG] aegis.log: 1234567890ABCDEFGHIJKLMNOPQRSTUVWXYZ%20%EA%B0%80%EB%82%98%EB%8B%A4%EB%9D%BC%EB%A7%88%EB%B0%94%EC%82%AC%EC%95%84%EC%9E%90%EC%B0%A8%EC%B9%B4%ED%83%80%ED%8C%8C%ED%95%98
2019-01-16 03:30:54,868 [DEBUG] aegis.log: b'1234567890ABCDEFGHIJKLMNOPQRSTUVWXYZ%20%EA%B0%80%EB%82%98%EB%8B%A4%EB%9D%BC%EB%A7%88%EB%B0%94%EC%82%AC%EC%95%84%EC%9E%90%EC%B0%A8%EC%B9%B4%ED%83%80%ED%8C%8C%ED%95%98'
2019-01-16 03:31:12,909 [DEBUG] aegis.log: >>> testDecryptionStr: bPRlRWGlo2jEJ0o1UuzqFG_-YCFOJLZn9LFk_213X0rbrALoPyF3x1YhRobhUdJCvk13FUA8Xrs4F0aajD3r-4ak9GYxYD97Plo1CAtxtS77Z7rsYFqTak_JKo3pSCTm
2019-01-16 03:31:12,972 [ERROR] django.request: Internal Server Error: /dr/testDecryptionStr
Traceback (most recent call last):
  File "/Volumes/Work/ddtech/ddtenv/lib/python3.6/site-packages/django/core/handlers/exception.py", line 34, in inner
    response = get_response(request)
  File "/Volumes/Work/ddtech/ddtenv/lib/python3.6/site-packages/django/core/handlers/base.py", line 126, in _get_response
    response = self.process_exception_by_middleware(e, request)
  File "/Volumes/Work/ddtech/ddtenv/lib/python3.6/site-packages/django/core/handlers/base.py", line 124, in _get_response
    response = wrapped_callback(request, *callback_args, **callback_kwargs)
  File "/Volumes/Work/ddtech/ddtenv/lib/python3.6/site-packages/django/views/decorators/csrf.py", line 54, in wrapped_view
    return view_func(*args, **kwargs)
  File "/Volumes/Work/ddtech/aegis/config/secret.py", line 207, in testDecryptionStr
    _cipherText = base64decode(_b64CipherText)
NameError: name 'base64decode' is not defined
2019-01-16 03:32:52,859 [DEBUG] aegis.log: >>> testDecryptionStr: bPRlRWGlo2jEJ0o1UuzqFG_-YCFOJLZn9LFk_213X0rbrALoPyF3x1YhRobhUdJCvk13FUA8Xrs4F0aajD3r-4ak9GYxYD97Plo1CAtxtS77Z7rsYFqTak_JKo3pSCTm
2019-01-16 03:32:52,924 [ERROR] django.request: Internal Server Error: /dr/testDecryptionStr
Traceback (most recent call last):
  File "/Volumes/Work/ddtech/ddtenv/lib/python3.6/site-packages/django/core/handlers/exception.py", line 34, in inner
    response = get_response(request)
  File "/Volumes/Work/ddtech/ddtenv/lib/python3.6/site-packages/django/core/handlers/base.py", line 126, in _get_response
    response = self.process_exception_by_middleware(e, request)
  File "/Volumes/Work/ddtech/ddtenv/lib/python3.6/site-packages/django/core/handlers/base.py", line 124, in _get_response
    response = wrapped_callback(request, *callback_args, **callback_kwargs)
  File "/Volumes/Work/ddtech/ddtenv/lib/python3.6/site-packages/django/views/decorators/csrf.py", line 54, in wrapped_view
    return view_func(*args, **kwargs)
  File "/Volumes/Work/ddtech/aegis/config/secret.py", line 207, in testDecryptionStr
    plainText = AES_DECRYPT_BASE64(_b64CipherText)
  File "/Volumes/Work/ddtech/aegis/config/secret.py", line 84, in AES_DECRYPT_BASE64
    msg = base64.b64decode(bytes(msg, encoding='utf-8'))
  File "/Library/Frameworks/Python.framework/Versions/3.6/lib/python3.6/base64.py", line 87, in b64decode
    return binascii.a2b_base64(s)
binascii.Error: Incorrect padding
2019-01-16 03:34:12,162 [DEBUG] aegis.log: >>> testDecryptionStr: 540c91671b9ead40238220ea87d580c7532f36a6fe8c27c8377b1c830a9489b4dfa36796dc017d0c1c1e6c7ac27d0d8479ee6ee0686d3cbe17d614e71e02afd99e13dedebbba322fbbbc1cb66469d4d89d8add97c098c7e2aead2d49938cdfafef0c3e4fc2350091f96c8d375a01bb349cf895ab9b7bc4bfad137b6cacce36bdaee104d346d634211658bf18c9c4f3518d424ce67b87ee3a210aca60113a16cff88cf8262648155ecb07c2090250005a
2019-01-16 03:34:12,194 [ERROR] django.request: Internal Server Error: /dr/testDecryptionStr
Traceback (most recent call last):
  File "/Volumes/Work/ddtech/ddtenv/lib/python3.6/site-packages/django/core/handlers/exception.py", line 34, in inner
    response = get_response(request)
  File "/Volumes/Work/ddtech/ddtenv/lib/python3.6/site-packages/django/core/handlers/base.py", line 126, in _get_response
    response = self.process_exception_by_middleware(e, request)
  File "/Volumes/Work/ddtech/ddtenv/lib/python3.6/site-packages/django/core/handlers/base.py", line 124, in _get_response
    response = wrapped_callback(request, *callback_args, **callback_kwargs)
  File "/Volumes/Work/ddtech/ddtenv/lib/python3.6/site-packages/django/views/decorators/csrf.py", line 54, in wrapped_view
    return view_func(*args, **kwargs)
  File "/Volumes/Work/ddtech/aegis/config/secret.py", line 207, in testDecryptionStr
    plainText = AES_DECRYPT_BASE64(_b64CipherText)
  File "/Volumes/Work/ddtech/aegis/config/secret.py", line 85, in AES_DECRYPT_BASE64
    return AES_DECRYPT(msg)
  File "/Volumes/Work/ddtech/aegis/config/secret.py", line 78, in AES_DECRYPT
    dec = AES.new(AESkey, AES.MODE_CBC, AESiv).decrypt(msg)
  File "/Volumes/Work/ddtech/ddtenv/lib/python3.6/site-packages/Crypto/Cipher/blockalgo.py", line 295, in decrypt
    return self._cipher.decrypt(ciphertext)
ValueError: Input strings must be a multiple of 16 in length
2019-01-16 03:34:12,253 [WARNING] django.request: Not Found: /favicon.ico
2019-01-16 03:36:02,749 [WARNING] django.request: Not Found: /
2019-01-16 03:36:02,900 [WARNING] django.request: Not Found: /favicon.ico
2019-01-16 03:36:18,404 [DEBUG] aegis.log: >>> testDecryptionStr: abcd%EA%B0%80%EA%B0%80%EA%B0%80%EA%B0%80%EA%B0%91%E3%85%82%E3%85%82%E3%85%82%E3%85%82
2019-01-16 03:36:18,433 [ERROR] django.request: Internal Server Error: /testDecryptionStr
Traceback (most recent call last):
  File "/Volumes/Work/ddtech/ddtenv/lib/python3.6/site-packages/django/core/handlers/exception.py", line 34, in inner
    response = get_response(request)
  File "/Volumes/Work/ddtech/ddtenv/lib/python3.6/site-packages/django/core/handlers/base.py", line 126, in _get_response
    response = self.process_exception_by_middleware(e, request)
  File "/Volumes/Work/ddtech/ddtenv/lib/python3.6/site-packages/django/core/handlers/base.py", line 124, in _get_response
    response = wrapped_callback(request, *callback_args, **callback_kwargs)
  File "/Volumes/Work/ddtech/ddtenv/lib/python3.6/site-packages/django/views/decorators/csrf.py", line 54, in wrapped_view
    return view_func(*args, **kwargs)
  File "/Volumes/Work/ddtech/aegis/config/secret.py", line 207, in testDecryptionStr
    plainText = AES_DECRYPT_BASE64(_b64CipherText)
  File "/Volumes/Work/ddtech/aegis/config/secret.py", line 84, in AES_DECRYPT_BASE64
    msg = base64.b64decode(bytes(msg, encoding='utf-8'))
  File "/Library/Frameworks/Python.framework/Versions/3.6/lib/python3.6/base64.py", line 87, in b64decode
    return binascii.a2b_base64(s)
binascii.Error: Incorrect padding
2019-01-16 03:36:36,175 [DEBUG] aegis.log: >>> testDecryptionStr: abcd%EA%B0%80%EA%B0%80%EA%B0%80%EA%B0%80%EA%B0%91%E3%85%82%E3%85%82%E3%85%82%E3%85%82
2019-01-16 03:36:36,205 [ERROR] django.request: Internal Server Error: /testDecryptionStr
Traceback (most recent call last):
  File "/Volumes/Work/ddtech/ddtenv/lib/python3.6/site-packages/django/core/handlers/exception.py", line 34, in inner
    response = get_response(request)
  File "/Volumes/Work/ddtech/ddtenv/lib/python3.6/site-packages/django/core/handlers/base.py", line 126, in _get_response
    response = self.process_exception_by_middleware(e, request)
  File "/Volumes/Work/ddtech/ddtenv/lib/python3.6/site-packages/django/core/handlers/base.py", line 124, in _get_response
    response = wrapped_callback(request, *callback_args, **callback_kwargs)
  File "/Volumes/Work/ddtech/ddtenv/lib/python3.6/site-packages/django/views/decorators/csrf.py", line 54, in wrapped_view
    return view_func(*args, **kwargs)
  File "/Volumes/Work/ddtech/aegis/config/secret.py", line 207, in testDecryptionStr
    plainText = AES_DECRYPT_BASE64(_b64CipherText)
  File "/Volumes/Work/ddtech/aegis/config/secret.py", line 84, in AES_DECRYPT_BASE64
    msg = base64.b64decode(bytes(msg, encoding='utf-8'))
  File "/Library/Frameworks/Python.framework/Versions/3.6/lib/python3.6/base64.py", line 87, in b64decode
    return binascii.a2b_base64(s)
binascii.Error: Incorrect padding
2019-01-16 03:36:47,030 [DEBUG] aegis.log: >>> testEncryptionStr: abcd%EA%B0%80%EA%B0%80%EA%B0%80%EA%B0%80%EA%B0%91%E3%85%82%E3%85%82%E3%85%82%E3%85%82
2019-01-16 03:36:47,030 [DEBUG] aegis.log: abcd%EA%B0%80%EA%B0%80%EA%B0%80%EA%B0%80%EA%B0%91%E3%85%82%E3%85%82%E3%85%82%E3%85%82
2019-01-16 03:36:47,030 [DEBUG] aegis.log: b'abcd%EA%B0%80%EA%B0%80%EA%B0%80%EA%B0%80%EA%B0%91%E3%85%82%E3%85%82%E3%85%82%E3%85%82'
2019-01-16 03:37:07,275 [DEBUG] aegis.log: >>> testDecryptionStr: a5a7b9de54fad66dbe907e1675df8fd19fdd55c351a696988fd5c3c9cd526c211a9d725f1f45b946909aa8f41fb5d38b5cbb6228f1d764cfc2e5d6b7954abc8b6ad6467dc1d412373d905504ced36412301e01919ee4169d7469c0cab252f51f
2019-01-16 03:37:07,305 [ERROR] django.request: Internal Server Error: /testDecryptionStr
Traceback (most recent call last):
  File "/Volumes/Work/ddtech/ddtenv/lib/python3.6/site-packages/django/core/handlers/exception.py", line 34, in inner
    response = get_response(request)
  File "/Volumes/Work/ddtech/ddtenv/lib/python3.6/site-packages/django/core/handlers/base.py", line 126, in _get_response
    response = self.process_exception_by_middleware(e, request)
  File "/Volumes/Work/ddtech/ddtenv/lib/python3.6/site-packages/django/core/handlers/base.py", line 124, in _get_response
    response = wrapped_callback(request, *callback_args, **callback_kwargs)
  File "/Volumes/Work/ddtech/ddtenv/lib/python3.6/site-packages/django/views/decorators/csrf.py", line 54, in wrapped_view
    return view_func(*args, **kwargs)
  File "/Volumes/Work/ddtech/aegis/config/secret.py", line 207, in testDecryptionStr
    plainText = AES_DECRYPT_BASE64(_b64CipherText)
  File "/Volumes/Work/ddtech/aegis/config/secret.py", line 85, in AES_DECRYPT_BASE64
    return AES_DECRYPT(msg)
  File "/Volumes/Work/ddtech/aegis/config/secret.py", line 79, in AES_DECRYPT
    return unpad(dec, 16)
  File "/Volumes/Work/ddtech/aegis/config/secret.py", line 48, in unpad
    raise ValueError("Padding is incorrect.")
ValueError: Padding is incorrect.
2019-01-16 03:38:13,111 [DEBUG] aegis.log: >>> testDecryptionStr: 540c91671b9ead40238220ea87d580c7532f36a6fe8c27c8377b1c830a9489b4dfa36796dc017d0c1c1e6c7ac27d0d8479ee6ee0686d3cbe17d614e71e02afd99e13dedebbba322fbbbc1cb66469d4d89d8add97c098c7e2aead2d49938cdfafef0c3e4fc2350091f96c8d375a01bb349cf895ab9b7bc4bfad137b6cacce36bdaee104d346d634211658bf18c9c4f3518d424ce67b87ee3a210aca60113a16cff88cf8262648155ecb07c2090250005a
2019-01-16 03:38:13,142 [ERROR] django.request: Internal Server Error: /dr/testDecryptionStr
Traceback (most recent call last):
  File "/Volumes/Work/ddtech/ddtenv/lib/python3.6/site-packages/django/core/handlers/exception.py", line 34, in inner
    response = get_response(request)
  File "/Volumes/Work/ddtech/ddtenv/lib/python3.6/site-packages/django/core/handlers/base.py", line 126, in _get_response
    response = self.process_exception_by_middleware(e, request)
  File "/Volumes/Work/ddtech/ddtenv/lib/python3.6/site-packages/django/core/handlers/base.py", line 124, in _get_response
    response = wrapped_callback(request, *callback_args, **callback_kwargs)
  File "/Volumes/Work/ddtech/ddtenv/lib/python3.6/site-packages/django/views/decorators/csrf.py", line 54, in wrapped_view
    return view_func(*args, **kwargs)
  File "/Volumes/Work/ddtech/aegis/config/secret.py", line 207, in testDecryptionStr
    plainText = AES_DECRYPT_BASE64(_b64CipherText)
  File "/Volumes/Work/ddtech/aegis/config/secret.py", line 85, in AES_DECRYPT_BASE64
    return AES_DECRYPT(msg)
  File "/Volumes/Work/ddtech/aegis/config/secret.py", line 78, in AES_DECRYPT
    dec = AES.new(AESkey, AES.MODE_CBC, AESiv).decrypt(msg)
  File "/Volumes/Work/ddtech/ddtenv/lib/python3.6/site-packages/Crypto/Cipher/blockalgo.py", line 295, in decrypt
    return self._cipher.decrypt(ciphertext)
ValueError: Input strings must be a multiple of 16 in length
2019-01-16 03:38:16,311 [DEBUG] aegis.log: >>> testDecryptionStr: 9qCWsIER64A2L06V12icebFeWqEamBod8nzgEEAwZ9g=
2019-01-16 03:39:20,658 [DEBUG] aegis.log: >>> testEncryptionStr: 1234567890ABCDEFGHIJKLMNOPQRSTUVWXYZ%20%EA%B0%80%EB%82%98%EB%8B%A4%EB%9D%BC%EB%A7%88%EB%B0%94%EC%82%AC%EC%95%84%EC%9E%90%EC%B0%A8%EC%B9%B4%ED%83%80%ED%8C%8C%ED%95%98
2019-01-16 03:39:20,658 [DEBUG] aegis.log: 1234567890ABCDEFGHIJKLMNOPQRSTUVWXYZ%20%EA%B0%80%EB%82%98%EB%8B%A4%EB%9D%BC%EB%A7%88%EB%B0%94%EC%82%AC%EC%95%84%EC%9E%90%EC%B0%A8%EC%B9%B4%ED%83%80%ED%8C%8C%ED%95%98
2019-01-16 03:39:20,721 [ERROR] django.request: Internal Server Error: /testEncryptionStr
Traceback (most recent call last):
  File "/Volumes/Work/ddtech/ddtenv/lib/python3.6/site-packages/django/core/handlers/exception.py", line 34, in inner
    response = get_response(request)
  File "/Volumes/Work/ddtech/ddtenv/lib/python3.6/site-packages/django/core/handlers/base.py", line 126, in _get_response
    response = self.process_exception_by_middleware(e, request)
  File "/Volumes/Work/ddtech/ddtenv/lib/python3.6/site-packages/django/core/handlers/base.py", line 124, in _get_response
    response = wrapped_callback(request, *callback_args, **callback_kwargs)
  File "/Volumes/Work/ddtech/ddtenv/lib/python3.6/site-packages/django/views/decorators/csrf.py", line 54, in wrapped_view
    return view_func(*args, **kwargs)
  File "/Volumes/Work/ddtech/aegis/config/secret.py", line 173, in testEncryptionStr
    r += '</br>*** cipherText(bytes) = ' + _cipherText
TypeError: must be str, not bytes
2019-01-16 03:40:07,391 [DEBUG] aegis.log: >>> testEncryptionStr: 1234567890ABCDEFGHIJKLMNOPQRSTUVWXYZ%20%EA%B0%80%EB%82%98%EB%8B%A4%EB%9D%BC%EB%A7%88%EB%B0%94%EC%82%AC%EC%95%84%EC%9E%90%EC%B0%A8%EC%B9%B4%ED%83%80%ED%8C%8C%ED%95%98
2019-01-16 03:40:07,391 [DEBUG] aegis.log: 1234567890ABCDEFGHIJKLMNOPQRSTUVWXYZ%20%EA%B0%80%EB%82%98%EB%8B%A4%EB%9D%BC%EB%A7%88%EB%B0%94%EC%82%AC%EC%95%84%EC%9E%90%EC%B0%A8%EC%B9%B4%ED%83%80%ED%8C%8C%ED%95%98
2019-01-16 03:40:07,391 [DEBUG] aegis.log: b'1234567890ABCDEFGHIJKLMNOPQRSTUVWXYZ%20%EA%B0%80%EB%82%98%EB%8B%A4%EB%9D%BC%EB%A7%88%EB%B0%94%EC%82%AC%EC%95%84%EC%9E%90%EC%B0%A8%EC%B9%B4%ED%83%80%ED%8C%8C%ED%95%98'
2019-01-16 03:40:21,865 [DEBUG] aegis.log: >>> testDecryptionStr: VAyRZxuerUAjgiDqh9WAx1MvNqb+jCfIN3scgwqUibTfo2eW3AF9DBwebHrCfQ2Eee5u4GhtPL4X1hTnHgKv2Z4T3t67ujIvu7wctmRp1Nidit2XwJjH4q6tLUmTjN+v7ww+T8I1AJH5bI03WgG7NJz4laube8S/rRN7bKzONr2u4QTTRtY0IRZYvxjJxPNRjUJM5nuH7johCspgEToWz/iM+CYmSBVeywfCCQJQAFo=
2019-01-16 03:40:21,915 [WARNING] django.request: Not Found: /favicon.ico
2019-01-16 03:40:40,692 [DEBUG] aegis.log: >>> testEncryptionStr: %EA%B0%80%EB%82%98%EB%8B%A4%EB%9D%BC%EB%A7%88%EB%B0%94%EC%82%AC%EC%95%84%EC%9E%90%EC%B0%A8%EC%B9%B4%ED%83%80%ED%8C%8C123
2019-01-16 03:40:40,692 [DEBUG] aegis.log: %EA%B0%80%EB%82%98%EB%8B%A4%EB%9D%BC%EB%A7%88%EB%B0%94%EC%82%AC%EC%95%84%EC%9E%90%EC%B0%A8%EC%B9%B4%ED%83%80%ED%8C%8C123
2019-01-16 03:40:40,692 [DEBUG] aegis.log: b'%EA%B0%80%EB%82%98%EB%8B%A4%EB%9D%BC%EB%A7%88%EB%B0%94%EC%82%AC%EC%95%84%EC%9E%90%EC%B0%A8%EC%B9%B4%ED%83%80%ED%8C%8C123'
2019-01-16 03:41:01,367 [DEBUG] aegis.log: >>> testDecryptionStr: +ofboMQKNARI9Zx6GRq/VQKTXp5jSRUuRXWWPkyi+xzEPncBX3GUDgTgS9Hv9SUSH9xx+Odc2it5YcE7kBz31BwBRnHSNKzizgGLvZFTjmzttSfN7xbRln06/R7ijp1fFQzNUanRq49kk+8egcNh2pu8xrVrpPxq8Jl2oU8jZcM=
2019-01-16 03:51:29,643 [WARNING] django.request: Not Found: /
2019-01-16 03:51:36,372 [ERROR] django.request: Service Unavailable: /check_version
2019-01-16 03:51:36,399 [WARNING] django.request: Not Found: /favicon.ico
2019-01-16 03:56:38,607 [ERROR] django.request: Service Unavailable: /employee/check_version
2019-01-16 03:56:38,629 [WARNING] django.request: Not Found: /favicon.ico
2019-01-16 03:56:49,501 [WARNING] django.request: Not Found: /check_version
2019-01-16 03:56:51,458 [WARNING] django.request: Not Found: /check_version
2019-01-16 05:39:28,295 [WARNING] django.request: Not Found: /check_version
2019-01-16 05:39:41,755 [ERROR] django.request: Service Unavailable: /employee/check_version
2019-01-16 05:39:42,367 [ERROR] django.request: Service Unavailable: /employee/check_version
2019-01-16 05:39:46,223 [ERROR] django.request: Service Unavailable: /employee/check_version
2019-01-16 05:39:53,902 [DEBUG] aegis.log: passer_reg >>> 503 ERROR: local variable 'response' referenced before assignment
2019-01-16 05:39:53,926 [WARNING] django.request: Not Found: /favicon.ico
2019-01-16 05:42:17,391 [WARNING] django.request: Not Found: /favicon.ico
2019-01-16 05:42:23,735 [WARNING] django.request: Not Found: /favicon.ico
2019-01-16 05:42:28,486 [ERROR] django.request: Service Unavailable: /employee/check_version
2019-01-16 05:42:50,577 [WARNING] django.request: Not Found: /employee/beacon_veriry
2019-01-16 05:42:50,595 [WARNING] django.request: Not Found: /favicon.ico
2019-01-16 05:42:55,395 [WARNING] django.request: Not Found: /employee/beacon_veriry
2019-01-16 05:42:59,337 [WARNING] django.request: Not Found: /employee/beacon_verify
2019-01-16 05:42:59,357 [WARNING] django.request: Not Found: /favicon.ico
2019-01-16 05:43:03,263 [WARNING] django.request: Not Found: /employee/beacon_verify
2019-01-16 05:43:05,331 [ERROR] django.request: Service Unavailable: /employee/check_version
2019-01-16 05:43:13,215 [WARNING] django.request: Not Found: /favicon.ico
2019-01-16 05:43:24,169 [WARNING] django.request: Not Found: /employee/vefiry_employee
2019-01-16 05:43:24,188 [WARNING] django.request: Not Found: /favicon.ico
2019-01-16 05:43:38,329 [WARNING] django.request: Not Found: /favicon.ico
2019-01-16 05:48:58,344 [DEBUG] aegis.log: >>> testDecryptionStr: 540c91671b9ead40238220ea87d580c7532f36a6fe8c27c8377b1c830a9489b4dfa36796dc017d0c1c1e6c7ac27d0d8479ee6ee0686d3cbe17d614e71e02afd99e13dedebbba322fbbbc1cb66469d4d89d8add97c098c7e2aead2d49938cdfafef0c3e4fc2350091f96c8d375a01bb349cf895ab9b7bc4bfad137b6cacce36bdaee104d346d634211658bf18c9c4f3518d424ce67b87ee3a210aca60113a16cff88cf8262648155ecb07c2090250005a
2019-01-16 05:48:58,406 [ERROR] django.request: Internal Server Error: /dr/testDecryptionStr
Traceback (most recent call last):
  File "/Volumes/Work/ddtech/ddtenv/lib/python3.6/site-packages/django/core/handlers/exception.py", line 34, in inner
    response = get_response(request)
  File "/Volumes/Work/ddtech/ddtenv/lib/python3.6/site-packages/django/core/handlers/base.py", line 126, in _get_response
    response = self.process_exception_by_middleware(e, request)
  File "/Volumes/Work/ddtech/ddtenv/lib/python3.6/site-packages/django/core/handlers/base.py", line 124, in _get_response
    response = wrapped_callback(request, *callback_args, **callback_kwargs)
  File "/Volumes/Work/ddtech/ddtenv/lib/python3.6/site-packages/django/views/decorators/csrf.py", line 54, in wrapped_view
    return view_func(*args, **kwargs)
  File "/Volumes/Work/ddtech/aegis/config/secret.py", line 132, in testDecryptionStr
    plainText = AES_DECRYPT_BASE64(_b64CipherText)
  File "/Volumes/Work/ddtech/aegis/config/secret.py", line 85, in AES_DECRYPT_BASE64
    return AES_DECRYPT(msg)
  File "/Volumes/Work/ddtech/aegis/config/secret.py", line 78, in AES_DECRYPT
    dec = AES.new(AESkey, AES.MODE_CBC, AESiv).decrypt(msg)
  File "/Volumes/Work/ddtech/ddtenv/lib/python3.6/site-packages/Crypto/Cipher/blockalgo.py", line 295, in decrypt
    return self._cipher.decrypt(ciphertext)
ValueError: Input strings must be a multiple of 16 in length
2019-01-16 05:49:23,474 [DEBUG] aegis.log: >>> testDecryptionStr: qgf6YHf1z2Fx80DR8o/Lvg
2019-01-16 05:49:23,503 [ERROR] django.request: Internal Server Error: /dr/testDecryptionStr
Traceback (most recent call last):
  File "/Volumes/Work/ddtech/ddtenv/lib/python3.6/site-packages/django/core/handlers/exception.py", line 34, in inner
    response = get_response(request)
  File "/Volumes/Work/ddtech/ddtenv/lib/python3.6/site-packages/django/core/handlers/base.py", line 126, in _get_response
    response = self.process_exception_by_middleware(e, request)
  File "/Volumes/Work/ddtech/ddtenv/lib/python3.6/site-packages/django/core/handlers/base.py", line 124, in _get_response
    response = wrapped_callback(request, *callback_args, **callback_kwargs)
  File "/Volumes/Work/ddtech/ddtenv/lib/python3.6/site-packages/django/views/decorators/csrf.py", line 54, in wrapped_view
    return view_func(*args, **kwargs)
  File "/Volumes/Work/ddtech/aegis/config/secret.py", line 132, in testDecryptionStr
    plainText = AES_DECRYPT_BASE64(_b64CipherText)
  File "/Volumes/Work/ddtech/aegis/config/secret.py", line 84, in AES_DECRYPT_BASE64
    msg = base64.b64decode(bytes(msg, encoding='utf-8'))
  File "/Library/Frameworks/Python.framework/Versions/3.6/lib/python3.6/base64.py", line 87, in b64decode
    return binascii.a2b_base64(s)
binascii.Error: Incorrect padding
2019-01-16 05:49:23,588 [WARNING] django.request: Not Found: /favicon.ico
2019-01-16 05:49:59,905 [DEBUG] aegis.log: >>> testDecryptionStr: qgf6YHf1z2Fx80DR8o/Lvg==
2019-01-16 05:49:59,929 [WARNING] django.request: Not Found: /favicon.ico
2019-01-16 05:54:03,510 [DEBUG] aegis.log: >>> testDecryptionStr: qgf6YHf1z2Fx80DR8o/Lvg==
2019-01-16 05:54:03,572 [ERROR] django.request: Internal Server Error: /dr/testDecryptionStr
Traceback (most recent call last):
  File "/Volumes/Work/ddtech/ddtenv/lib/python3.6/site-packages/django/core/handlers/exception.py", line 34, in inner
    response = get_response(request)
  File "/Volumes/Work/ddtech/ddtenv/lib/python3.6/site-packages/django/core/handlers/base.py", line 126, in _get_response
    response = self.process_exception_by_middleware(e, request)
  File "/Volumes/Work/ddtech/ddtenv/lib/python3.6/site-packages/django/core/handlers/base.py", line 124, in _get_response
    response = wrapped_callback(request, *callback_args, **callback_kwargs)
  File "/Volumes/Work/ddtech/ddtenv/lib/python3.6/site-packages/django/views/decorators/csrf.py", line 54, in wrapped_view
    return view_func(*args, **kwargs)
  File "/Volumes/Work/ddtech/aegis/config/secret.py", line 133, in testDecryptionStr
    r += '</br>*** base64 cipherText = ' + _b64CipherText
TypeError: must be str, not bytes
2019-01-16 05:58:40,081 [DEBUG] aegis.log: >>> testDecryptionStr: qgf6YHf1z2Fx80DR8o/Lvg==
2019-01-16 05:58:59,568 [DEBUG] aegis.log: >>> testDecryptionStr: qgf6YHf1z2Fx80DR8o/Lvg==
2019-01-16 05:58:59,732 [DEBUG] aegis.log: >>> testDecryptionStr: qgf6YHf1z2Fx80DR8o/Lvg
2019-01-16 05:59:01,630 [DEBUG] aegis.log: >>> testDecryptionStr: qgf6YHf1z2Fx80DR8o/Lvg
2019-01-16 06:00:27,282 [DEBUG] aegis.log: >>> testDecryptionStr: qgf6YHf1z2Fx80DR8o/Lvg
2019-01-16 06:00:27,345 [ERROR] django.request: Internal Server Error: /dr/testDecryptionStr
Traceback (most recent call last):
  File "/Volumes/Work/ddtech/ddtenv/lib/python3.6/site-packages/django/core/handlers/exception.py", line 34, in inner
    response = get_response(request)
  File "/Volumes/Work/ddtech/ddtenv/lib/python3.6/site-packages/django/core/handlers/base.py", line 126, in _get_response
    response = self.process_exception_by_middleware(e, request)
  File "/Volumes/Work/ddtech/ddtenv/lib/python3.6/site-packages/django/core/handlers/base.py", line 124, in _get_response
    response = wrapped_callback(request, *callback_args, **callback_kwargs)
  File "/Volumes/Work/ddtech/ddtenv/lib/python3.6/site-packages/django/views/decorators/csrf.py", line 54, in wrapped_view
    return view_func(*args, **kwargs)
  File "/Volumes/Work/ddtech/aegis/config/secret.py", line 137, in testDecryptionStr
    plainText = AES_DECRYPT_BASE64(_b64CipherText)
  File "/Volumes/Work/ddtech/aegis/config/secret.py", line 84, in AES_DECRYPT_BASE64
    pad = '=' * (-len(_b64CipherText) % 4)
NameError: name '_b64CipherText' is not defined
2019-01-16 06:00:52,820 [DEBUG] aegis.log: >>> testDecryptionStr: qgf6YHf1z2Fx80DR8o/Lvg
2019-01-16 06:02:49,966 [DEBUG] aegis.log: >>> testDecryptionStr: qgf6YHf1z2Fx80DR8o/Lvg
2019-01-16 06:07:43,813 [DEBUG] aegis.log: >>> testEncryptionStr: 1234567890ABCDEFGHIJKLMNOPQRSTUVWXYZ%20%EA%B0%80%EB%82%98%EB%8B%A4%EB%9D%BC%EB%A7%88%EB%B0%94%EC%82%AC%EC%95%84%EC%9E%90%EC%B0%A8%EC%B9%B4%ED%83%80%ED%8C%8C%ED%95%98
2019-01-16 06:07:43,814 [DEBUG] aegis.log: 1234567890ABCDEFGHIJKLMNOPQRSTUVWXYZ%20%EA%B0%80%EB%82%98%EB%8B%A4%EB%9D%BC%EB%A7%88%EB%B0%94%EC%82%AC%EC%95%84%EC%9E%90%EC%B0%A8%EC%B9%B4%ED%83%80%ED%8C%8C%ED%95%98
2019-01-16 06:07:43,814 [DEBUG] aegis.log: b'1234567890ABCDEFGHIJKLMNOPQRSTUVWXYZ%20%EA%B0%80%EB%82%98%EB%8B%A4%EB%9D%BC%EB%A7%88%EB%B0%94%EC%82%AC%EC%95%84%EC%9E%90%EC%B0%A8%EC%B9%B4%ED%83%80%ED%8C%8C%ED%95%98'
2019-01-16 06:07:43,832 [WARNING] django.request: Not Found: /favicon.ico
2019-01-16 21:58:11,931 [WARNING] django.request: Not Found: /
2019-01-16 21:58:32,082 [ERROR] django.request: Internal Server Error: /operation/reg_staff
Traceback (most recent call last):
  File "/Volumes/Work/ddtech/aegis/operation/views.py", line 18, in reg_staff
    response = HttpResponse()
NameError: name 'HttpResponse' is not defined

During handling of the above exception, another exception occurred:

Traceback (most recent call last):
  File "/Volumes/Work/ddtech/ddtenv/lib/python3.6/site-packages/django/core/handlers/exception.py", line 34, in inner
    response = get_response(request)
  File "/Volumes/Work/ddtech/ddtenv/lib/python3.6/site-packages/django/core/handlers/base.py", line 126, in _get_response
    response = self.process_exception_by_middleware(e, request)
  File "/Volumes/Work/ddtech/ddtenv/lib/python3.6/site-packages/django/core/handlers/base.py", line 124, in _get_response
    response = wrapped_callback(request, *callback_args, **callback_kwargs)
  File "/Volumes/Work/ddtech/aegis/operation/views.py", line 22, in reg_staff
    return exceptionError('reg_staff', '503', e)
NameError: name 'exceptionError' is not defined
2019-01-16 21:58:32,168 [WARNING] django.request: Not Found: /favicon.ico
2019-01-16 22:00:42,906 [WARNING] django.request: Not Found: /favicon.ico
2019-01-16 22:00:59,803 [WARNING] django.request: Not Found: /favicon.ico
2019-01-16 22:01:13,553 [WARNING] django.request: Not Found: /favicon.ico
2019-01-16 22:01:24,959 [WARNING] django.request: Not Found: /favicon.ico
2019-01-16 22:01:35,417 [WARNING] django.request: Not Found: /favicon.ico
2019-01-16 22:01:46,331 [WARNING] django.request: Not Found: /favicon.ico
2019-01-16 22:01:56,503 [WARNING] django.request: Not Found: /favicon.ico
